Workbook

Sheet 1
A1: DINERO EXPRESS #8 (512) 8015655 | H1: =A1 -> DINERO EXPRESS #8 (512) 8015655 | M1: DATE
A2: Daily Report | D2: Date: | H2: OTHER REPORTS | M2: 45269 | O2: Lottery Sale
D3: Day: | M3: =F3 -> 0 | O3: Game # | P3: Open | Q3: Close | R3: Tic.Sold | S3: $ Value | T3: T. Sale
A4: Reciepts | C4: Amount | D4: Disbursments | F4: Amount | H4: MONEY TRANSFER | N4: 1 | R4: =Q4-P4 -> 0 | S4: 50 | T4: =R4*S4 -> 0
A5: Taxable Sale | C5: 12 | D5: Cash Purchases | F5: =C40 -> 0 | H5: Company | I5: Amount | J5: Fees | K5: Commission | L5: Individual Total Amount | N5: 2 | R5: =Q5-P5 -> 0 | S5: 20 | T5: =R5*S5 -> 0
A6: Comm & Fee | C6: 12 | D6: Cash Expense | F6: =F40 -> 0 | H6: DINEX | L6: =SUM(I6:K6) -> 0 | N6: 3 | R6: =Q6-P6 -> 0 | S6: 20 | T6: =R6*S6 -> 0
A7: Sales Tax | D7: Check Purchases | F7: =C53 -> 0 | H7: INTERMEX | I7: 7254.97 | J7: 169 | L7: =SUM(I7:K7) -> 7423.97 | N7: 4 | R7: =Q7-P7 -> 0 | S7: 10 | T7: =R7*S7 -> 0
A8: Money Transfers | C8: =L14 -> 9830.3 | D8: Check Expense | F8: =F47 -> 0 | H8: SIGUE | L8: =SUM(I8:K8) -> 0 | N8: 5 | R8: =Q8-P8 -> 0 | S8: 10 | T8: =R8*S8 -> 0
A9: Lottery Sales | C9: =S52 -> 0 | D9: Lotto Paid Out | H9: AFEX | L9: =SUM(I9:K9) -> 0 | N9: 6 | R9: =Q9-P9 -> 0 | S9: 20 | T9: =R9*S9 -> 0
A10: Lotto Net Sales | D10: Lottery Paid Out | H10: MONEYGRAM | L10: =SUM(I10:K10) -> 0 | N10: 7 | R10: =Q10-P10 -> 0 | S10: 20 | T10: =R10*S10 -> 0
A11: PhoneCard | D11: ATM Drop | H11: BARRI | I11: 1316.03 | J11: 30 | L11: =SUM(I11:K11) -> 1346.03 | N11: 8 | R11: =Q11-P11 -> 0 | S11: 20 | T11: =R11*S11 -> 0
A12: Boss Revolution | D12: Credit Card | H12: MAXI | I12: 1010.3 | J12: 50 | L12: =SUM(I12:K12) -> 1060.3 | N12: 9 | R12: =Q12-P12 -> 0 | S12: 10 | T12: =R12*S12 -> 0
A13: Bill Payment | D13: Outside Cash & Drops | F13: =L40 -> 9830 | H13: AMIGO SIN PIN | L13: =SUM(I13:K13) -> 0 | N13: 10 | R13: =Q13-P13 -> 0 | S13: 10 | T13: =R13*S13 -> 0
A14: VidaPay | D14: Cash Deposit | H14: TOTAL | I14: =SUM(I6:I13) -> 9581.3 | J14: =SUM(J6:J13) -> 249 | K14: =SUM(K6:K13) -> 0 | L14: =SUM(L6:M13) -> 9830.3 | N14: 11 | R14: =Q14-P14 -> 0 | S14: 5 | T14: =R14*S14 -> 0
A15: Boost Epay | D15: Money Gram Payment | N15: 12 | R15: =Q15-P15 -> 0 | S15: 5 | T15: =R15*S15 -> 0
A16: Epay | D16: Vigo Payment | N16: 13 | R16: =Q16-P16 -> 0 | S16: 5 | T16: =R16*S16 -> 0
A17: Check Cashing Fees | C17: 131.48 | D17: Ria Payment | N17: 14 | R17: =Q17-P17 -> 0 | S17: 5 | T17: =R17*S17 -> 0
A18: Money Order | C18: 2958.51 | D18: Checks Deposit | F18: =J25 -> 26296.19 | H18: CHECK DEPOSITS | K18: DROPS | L18: AMOUNT | M18: TIME | N18: 15 | R18: =Q18-P18 -> 0 | S18: 5 | T18: =R18*S18 -> 0
A19: Return Check Paid | C19: =F33 -> 0 | D19: Safe Balance | F19: 50613 | H19: CHECK DEPOSITS TO BANK | J19: AMOUNT | K19: 1 | L19: 3000 | M19: 0.57083333 | N19: 16 | R19: =Q19-P19 -> 0 | S19: 5 | T19: =R19*S19 -> 0
A20: Forward Balance | C20: 55994 | D20: Payroll Expense | F20: =J40 -> 0 | H20: NIZARI (29 Checks) | J20: 26296.19 | K20: 2 | L20: 6830 | M20: 0.87708333 | N20: 17 | R20: =Q20-P20 -> 0 | S20: 5 | T20: =R20*S20 -> 0
A21: Cash From Bank | C21: 20000 | D21: Other Cash Out | F21: =M53 -> 2400 | K21: 3 | N21: 18 | R21: =Q21-P21 -> 0 | S21: 5 | T21: =R21*S21 -> 0
A22: Other Cash In | C22: =J53 -> 200 | D22: TOTAL PAYOUTS | F22: =SUM(F5:F21)-F7-F8 -> 89139.19 | K22: 4 | N22: 19 | R22: =Q22-P22 -> 0 | S22: 5 | T22: =R22*S22 -> 0
A23: Rebates & Commissions | C23: =F53 -> 0 | D23: Inside Over - (Short) | F23: =(F11+F14+F15+F16+F17+F18+F19+F20+F21+F5+F6)-(C17+C19+C20+C21+C22+C23) -> 2983.71 | K23: 5 | N23: 20 | R23: =Q23-P23 -> 0 | S23: 5 | T23: =R23*S23 -> 0
A24: TOTAL RECEIPTS | C24: =SUM(C5:C23) -> 89138.29 | D24: Over All Over - (Short) | F24: =SUM(F22-C24) -> 0.9 | K24: 6 | N24: 21 | R24: =Q24-P24 -> 0 | S24: 5 | T24: =R24*S24 -> 0
A25: Out Side Over - (Short) | C25: =(F9+F10+F12+F13)-(C5+C6+C7+C8+C9+C10+C11+C12+C13+C14+C15+C16+C18) -> -2982.81 | H25: TOTAL | J25: =SUM(J20:J24) -> 26296.19 | K25: 7 | N25: 22 | R25: =Q25-P25 -> 0 | S25: 5 | T25: =R25*S25 -> 0
A26: Cash Purchases | D26: Return Check Paid | K26: 8 | N26: 23 | R26: =Q26-P26 -> 0 | S26: 3 | T26: =R26*S26 -> 0
A27: Description | C27: Amount | D27: Description | F27: Amount | K27: 9 | N27: 24 | R27: =Q27-P27 -> 0 | S27: 3 | T27: =R27*S27 -> 0
H28: CASH PAYROLL EXPENSE | K28: 10 | N28: 25 | R28: =Q28-P28 -> 0 | S28: 2 | T28: =R28*S28 -> 0
H29: CASH PAYROLL PAID TO | J29: AMOUNT | K29: 11 | N29: 26 | R29: =Q29-P29 -> 0 | S29: 5 | T29: =R29*S29 -> 0
K30: 12 | N30: 27 | R30: =Q30-P30 -> 0 | S30: 3 | T30: =R30*S30 -> 0
K31: 13 | N31: 28 | R31: =Q31-P31 -> 0 | S31: 3 | T31: =R31*S31 -> 0
K32: 14 | N32: 29 | R32: =Q32-P32 -> 0 | S32: 2 | T32: =R32*S32 -> 0
D33: Total | F33: =SUM(F28:F32) -> 0 | K33: 15 | N33: 30 | R33: =Q33-P33 -> 0 | S33: 2 | T33: =R33*S33 -> 0
D34: Cash Expense | K34: 16 | N34: 31 | R34: =Q34-P34 -> 0 | S34: 2 | T34: =R34*S34 -> 0
D35: Description | F35: Amount | K35: 17 | N35: 32 | R35: =Q35-P35 -> 0 | S35: 2 | T35: =R35*S35 -> 0
K36: 18 | N36: 33 | R36: =Q36-P36 -> 0 | S36: 2 | T36: =R36*S36 -> 0
K37: 19 | N37: 34 | R37: =Q37-P37 -> 0 | S37: 1 | T37: =R37*S37 -> 0
K38: 20 | N38: 35 | R38: =Q38-P38 -> 0 | S38: 1 | T38: =R38*S38 -> 0
K39: 21 | N39: 36 | R39: =Q39-P39 -> 0 | S39: 2 | T39: =R39*S39 -> 0
A40: Total | C40: =SUM(C28:C39) -> 0 | D40: Total | F40: =SUM(F36:F39) -> 0 | H40: TOTAL | J40: =SUM(J30:J39) -> 0 | K40: TOTAL | L40: =SUM(L19:L39) -> 9830 | N40: 37 | R40: =Q40-P40 -> 0 | S40: 2 | T40: =R40*S40 -> 0
...

Sheet 2
A1: ='1'!A1:F1 -> DINERO EXPRESS #8 (512) 8015655 | H1: =A1 -> DINERO EXPRESS #8 (512) 8015655 | M1: DATE
A2: Daily Report | D2: Date: | F2: ='1'!F2+1 -> 1 | H2: OTHER REPORTS | M2: =F2 -> 1 | O2: Lottery Sale
D3: Day: | M3: =F3 -> 0 | O3: Game # | P3: Open | Q3: Close | R3: Tic.Sold | S3: $ Value | T3: T. Sale
A4: Reciepts | C4: Amount | D4: Disbursments | F4: Amount | H4: MONEY TRANSFER | N4: 1 | P4: ='1'!Q4 -> 0 | R4: =Q4-P4 -> 0 | S4: 50 | T4: =R4*S4 -> 0
A5: ='1'!A5:B5 -> Taxable Sale | C5: 16 | D5: ='1'!D5:E5 -> Cash Purchases | F5: =C40 -> 0 | H5: Company | I5: Amount | J5: Fees | K5: Commission | L5: Individual Total Amount | N5: 2 | P5: ='1'!Q5 -> 0 | R5: =Q5-P5 -> 0 | S5: 20 | T5: =R5*S5 -> 0
A6: ='1'!A6:B6 -> Comm & Fee | D6: ='1'!D6:E6 -> Cash Expense | F6: =F40 -> 0 | H6: ='1'!H6 -> DINEX | L6: =SUM(I6:K6) -> 0 | N6: 3 | P6: ='1'!Q6 -> 0 | R6: =Q6-P6 -> 0 | S6: 20 | T6: =R6*S6 -> 0
A7: ='1'!A7:B7 -> Sales Tax | D7: ='1'!D7:E7 -> Check Purchases | F7: =C53 -> 0 | H7: ='1'!H7 -> INTERMEX | I7: 3308.31 | J7: 77.76 | L7: =SUM(I7:K7) -> 3386.07 | N7: 4 | P7: ='1'!Q7 -> 0 | R7: =Q7-P7 -> 0 | S7: 10 | T7: =R7*S7 -> 0
A8: ='1'!A8:B8 -> Money Transfers | C8: =L14 -> 4393.4 | D8: ='1'!D8:E8 -> Check Expense | F8: =F47 -> 0 | H8: ='1'!H8 -> SIGUE | L8: =SUM(I8:K8) -> 0 | N8: 5 | P8: ='1'!Q8 -> 0 | R8: =Q8-P8 -> 0 | S8: 10 | T8: =R8*S8 -> 0
A9: ='1'!A9:B9 -> Lottery Sales | C9: =S52 -> 0 | D9: ='1'!D9:E9 -> Lotto Paid Out | H9: ='1'!H9 -> AFEX | L9: =SUM(I9:K9) -> 0 | N9: 6 | P9: ='1'!Q9 -> 0 | R9: =Q9-P9 -> 0 | S9: 20 | T9: =R9*S9 -> 0
A10: ='1'!A10:B10 -> Lotto Net Sales | D10: ='1'!D10:E10 -> Lottery Paid Out | H10: ='1'!H10 -> MONEYGRAM | L10: =SUM(I10:K10) -> 0 | N10: 7 | P10: ='1'!Q10 -> 0 | R10: =Q10-P10 -> 0 | S10: 20 | T10: =R10*S10 -> 0
A11: ='1'!A11:B11 -> PhoneCard | D11: ='1'!D11:E11 -> ATM Drop | H11: ='1'!H11 -> BARRI | I11: 190.01 | J11: 12 | L11: =SUM(I11:K11) -> 202.01 | N11: 8 | P11: ='1'!Q11 -> 0 | R11: =Q11-P11 -> 0 | S11: 20 | T11: =R11*S11 -> 0
A12: ='1'!A12:B12 -> Boss Revolution | D12: ='1'!D12:E12 -> Credit Card | H12: ='1'!H12 -> MAXI | I12: 745.32 | J12: 60 | L12: =SUM(I12:K12) -> 805.32 | N12: 9 | P12: ='1'!Q12 -> 0 | R12: =Q12-P12 -> 0 | S12: 10 | T12: =R12*S12 -> 0
A13: ='1'!A13:B13 -> Bill Payment | D13: ='1'!D13:E13 -> Outside Cash & Drops | F13: =L40 -> 4393 | H13: ='1'!H13 -> AMIGO SIN PIN | L13: =SUM(I13:K13) -> 0 | N13: 10 | P13: ='1'!Q13 -> 0 | R13: =Q13-P13 -> 0 | S13: 10 | T13: =R13*S13 -> 0
A14: ='1'!A14:B14 -> VidaPay | D14: ='1'!D14:E14 -> Cash Deposit | H14: TOTAL | I14: =SUM(I6:I13) -> 4243.64 | J14: =SUM(J6:J13) -> 149.76 | K14: =SUM(K6:K13) -> 0 | L14: =SUM(L6:M13) -> 4393.4 | N14: 11 | P14: ='1'!Q14 -> 0 | R14: =Q14-P14 -> 0 | S14: 5 | T14: =R14*S14 -> 0
A15: ='1'!A15:B15 -> Boost Epay | D15: ='1'!D15:E15 -> Money Gram Payment | N15: 12 | P15: ='1'!Q15 -> 0 | R15: =Q15-P15 -> 0 | S15: 5 | T15: =R15*S15 -> 0
A16: ='1'!A16:B16 -> Epay | D16: ='1'!D16:E16 -> Vigo Payment | N16: 13 | P16: ='1'!Q16 -> 0 | R16: =Q16-P16 -> 0 | S16: 5 | T16: =R16*S16 -> 0
A17: ='1'!A17:B17 -> Check Cashing Fees | C17: 76.83 | D17: ='1'!D17:E17 -> Ria Payment | N17: 14 | P17: ='1'!Q17 -> 0 | R17: =Q17-P17 -> 0 | S17: 5 | T17: =R17*S17 -> 0
A18: ='1'!A18:B18 -> Money Order | C18: 9372.08 | D18: ='1'!D18:E18 -> Checks Deposit | F18: =J25 -> 15365.97 | H18: CHECK DEPOSITS | K18: DROPS | L18: AMOUNT | M18: TIME | N18: 15 | P18: ='1'!Q18 -> 0 | R18: =Q18-P18 -> 0 | S18: 5 | T18: =R18*S18 -> 0
A19: ='1'!A19:B19 -> Return Check Paid | C19: =F33 -> 1835 | D19: ='1'!D19:E19 -> Safe Balance | F19: 69478 | H19: CHECK DEPOSITS TO BANK | J19: AMOUNT | K19: 1 | L19: 3460 | M19: 0.62569444 | N19: 16 | P19: ='1'!Q19 -> 0 | R19: =Q19-P19 -> 0 | S19: 5 | T19: =R19*S19 -> 0
A20: ='1'!A20:B20 -> Forward Balance | C20: ='1'!F19+'1'!F13 -> 60443 | D20: ='1'!D20:E20 -> Payroll Expense | F20: =J40 -> 0 | H20: NIZARI (18 Checks) | J20: 15365.97 | K20: 2 | L20: 933 | M20: 0.87569444 | N20: 17 | P20: ='1'!Q20 -> 0 | R20: =Q20-P20 -> 0 | S20: 5 | T20: =R20*S20 -> 0
A21: ='1'!A21:B21 -> Cash From Bank | C21: 13000 | D21: ='1'!D21:E21 -> Other Cash Out | F21: =M53 -> 2300 | K21: 3 | N21: 18 | P21: ='1'!Q21 -> 0 | R21: =Q21-P21 -> 0 | S21: 5 | T21: =R21*S21 -> 0
A22: ='1'!A22:B22 -> Other Cash In | C22: =J53 -> 2400 | D22: TOTAL PAYOUTS | F22: =SUM(F5:F21)-F7-F8 -> 91536.97 | K22: 4 | N22: 19 | P22: ='1'!Q22 -> 0 | R22: =Q22-P22 -> 0 | S22: 5 | T22: =R22*S22 -> 0
A23: ='1'!A23:B23 -> Rebates & Commissions | C23: =F53 -> 0 | D23: Inside Over - (Short) | F23: =(F11+F14+F15+F16+F17+F18+F19+F20+F21+F5+F6)-(C17+C19+C20+C21+C22+C23) -> 9389.14 | K23: 5 | N23: 20 | P23: ='1'!Q23 -> 0 | R23: =Q23-P23 -> 0 | S23: 5 | T23: =R23*S23 -> 0
A24: TOTAL RECEIPTS | C24: =SUM(C5:C23) -> 91536.31 | D24: Over All Over - (Short) | F24: =SUM(F22-C24) -> 0.66 | K24: 6 | N24: 21 | P24: ='1'!Q24 -> 0 | R24: =Q24-P24 -> 0 | S24: 5 | T24: =R24*S24 -> 0
A25: Out Side Over - (Short) | C25: =(F9+F10+F12+F13)-(C5+C6+C7+C8+C9+C10+C11+C12+C13+C14+C15+C16+C18) -> -9388.48 | H25: TOTAL | J25: =SUM(J20:J24) -> 15365.97 | K25: 7 | N25: 22 | P25: ='1'!Q25 -> 0 | R25: =Q25-P25 -> 0 | S25: 5 | T25: =R25*S25 -> 0
A26: Cash Purchases | D26: Return Check Paid | K26: 8 | N26: 23 | P26: ='1'!Q26 -> 0 | R26: =Q26-P26 -> 0 | S26: 3 | T26: =R26*S26 -> 0
A27: Description | C27: Amount | D27: Description | F27: Amount | K27: 9 | N27: 24 | P27: ='1'!Q27 -> 0 | R27: =Q27-P27 -> 0 | S27: 3 | T27: =R27*S27 -> 0
D28: Barbara N Lampart | F28: 1835 | H28: CASH PAYROLL EXPENSE | K28: 10 | N28: 25 | P28: ='1'!Q28 -> 0 | R28: =Q28-P28 -> 0 | S28: 2 | T28: =R28*S28 -> 0
H29: CASH PAYROLL PAID TO | J29: AMOUNT | K29: 11 | N29: 26 | P29: ='1'!Q29 -> 0 | R29: =Q29-P29 -> 0 | S29: 5 | T29: =R29*S29 -> 0
K30: 12 | N30: 27 | P30: ='1'!Q30 -> 0 | R30: =Q30-P30 -> 0 | S30: 3 | T30: =R30*S30 -> 0
K31: 13 | N31: 28 | P31: ='1'!Q31 -> 0 | R31: =Q31-P31 -> 0 | S31: 3 | T31: =R31*S31 -> 0
K32: 14 | N32: 29 | P32: ='1'!Q32 -> 0 | R32: =Q32-P32 -> 0 | S32: 2 | T32: =R32*S32 -> 0
D33: Total | F33: =SUM(F28:F32) -> 1835 | K33: 15 | N33: 30 | P33: ='1'!Q33 -> 0 | R33: =Q33-P33 -> 0 | S33: 2 | T33: =R33*S33 -> 0
D34: Cash Expense | K34: 16 | N34: 31 | P34: ='1'!Q34 -> 0 | R34: =Q34-P34 -> 0 | S34: 2 | T34: =R34*S34 -> 0
D35: Description | F35: Amount | K35: 17 | N35: 32 | P35: ='1'!Q35 -> 0 | R35: =Q35-P35 -> 0 | S35: 2 | T35: =R35*S35 -> 0
K36: 18 | N36: 33 | P36: ='1'!Q36 -> 0 | R36: =Q36-P36 -> 0 | S36: 2 | T36: =R36*S36 -> 0
K37: 19 | N37: 34 | P37: ='1'!Q37 -> 0 | R37: =Q37-P37 -> 0 | S37: 1 | T37: =R37*S37 -> 0
K38: 20 | N38: 35 | P38: ='1'!Q38 -> 0 | R38: =Q38-P38 -> 0 | S38: 1 | T38: =R38*S38 -> 0
K39: 21 | N39: 36 | P39: ='1'!Q39 -> 0 | R39: =Q39-P39 -> 0 | S39: 2 | T39: =R39*S39 -> 0
A40: Total | C40: =SUM(C28:C39) -> 0 | D40: Total | F40: =SUM(F36:F39) -> 0 | H40: TOTAL | J40: =SUM(J30:J39) -> 0 | K40: TOTAL | L40: =SUM(L19:L39) -> 4393 | N40: 37 | P40: ='1'!Q40 -> 0 | R40: =Q40-P40 -> 0 | S40: 2 | T40: =R40*S40 -> 0
...

Sheet 3
A1: ='1'!A1:F1 -> DINERO EXPRESS #8 (512) 8015655 | H1: =A1 -> DINERO EXPRESS #8 (512) 8015655 | M1: DATE
A2: Daily Report | D2: Date: | F2: ='2'!F2+1 -> 2 | H2: OTHER REPORTS | M2: =F2 -> 2 | O2: Lottery Sale
D3: Day: | M3: =F3 -> 0 | O3: Game # | P3: Open | Q3: Close | R3: Tic.Sold | S3: $ Value | T3: T. Sale
A4: Reciepts | C4: Amount | D4: Disbursments | F4: Amount | H4: MONEY TRANSFER | N4: 1 | P4: ='2'!Q4 -> 0 | R4: =Q4-P4 -> 0 | S4: 50 | T4: =R4*S4 -> 0
A5: ='1'!A5:B5 -> Taxable Sale | D5: ='1'!D5:E5 -> Cash Purchases | F5: =C40 -> 0 | H5: Company | I5: Amount | J5: Fees | K5: Commission | L5: Individual Total Amount | N5: 2 | P5: ='2'!Q5 -> 0 | R5: =Q5-P5 -> 0 | S5: 20 | T5: =R5*S5 -> 0
A6: ='1'!A6:B6 -> Comm & Fee | C6: 25 | D6: ='1'!D6:E6 -> Cash Expense | F6: =F40 -> 0 | H6: ='1'!H6 -> DINEX | L6: =SUM(I6:K6) -> 0 | N6: 3 | P6: ='2'!Q6 -> 0 | R6: =Q6-P6 -> 0 | S6: 20 | T6: =R6*S6 -> 0
A7: ='1'!A7:B7 -> Sales Tax | D7: ='1'!D7:E7 -> Check Purchases | F7: =C53 -> 0 | H7: ='1'!H7 -> INTERMEX | I7: 9112.39 | J7: 192.5 | L7: =SUM(I7:K7) -> 9304.89 | N7: 4 | P7: ='2'!Q7 -> 0 | R7: =Q7-P7 -> 0 | S7: 10 | T7: =R7*S7 -> 0
A8: ='1'!A8:B8 -> Money Transfers | C8: =L14 -> 14755.09 | D8: ='1'!D8:E8 -> Check Expense | F8: =F47 -> 0 | H8: ='1'!H8 -> SIGUE | L8: =SUM(I8:K8) -> 0 | N8: 5 | P8: ='2'!Q8 -> 0 | R8: =Q8-P8 -> 0 | S8: 10 | T8: =R8*S8 -> 0
A9: ='1'!A9:B9 -> Lottery Sales | C9: =S52 -> 0 | D9: ='1'!D9:E9 -> Lotto Paid Out | H9: ='1'!H9 -> AFEX | L9: =SUM(I9:K9) -> 0 | N9: 6 | P9: ='2'!Q9 -> 0 | R9: =Q9-P9 -> 0 | S9: 20 | T9: =R9*S9 -> 0
A10: ='1'!A10:B10 -> Lotto Net Sales | D10: ='1'!D10:E10 -> Lottery Paid Out | H10: ='1'!H10 -> MONEYGRAM | L10: =SUM(I10:K10) -> 0 | N10: 7 | P10: ='2'!Q10 -> 0 | R10: =Q10-P10 -> 0 | S10: 20 | T10: =R10*S10 -> 0
A11: ='1'!A11:B11 -> PhoneCard | D11: ='1'!D11:E11 -> ATM Drop | H11: ='1'!H11 -> BARRI | I11: 1310 | J11: 20 | L11: =SUM(I11:K11) -> 1330 | N11: 8 | P11: ='2'!Q11 -> 0 | R11: =Q11-P11 -> 0 | S11: 20 | T11: =R11*S11 -> 0
A12: ='1'!A12:B12 -> Boss Revolution | D12: ='1'!D12:E12 -> Credit Card | H12: ='1'!H12 -> MAXI | I12: 4006.2 | J12: 114 | L12: =SUM(I12:K12) -> 4120.2 | N12: 9 | P12: ='2'!Q12 -> 0 | R12: =Q12-P12 -> 0 | S12: 10 | T12: =R12*S12 -> 0
A13: ='1'!A13:B13 -> Bill Payment | D13: ='1'!D13:E13 -> Outside Cash & Drops | F13: =L40 -> 14755 | H13: ='1'!H13 -> AMIGO SIN PIN | L13: =SUM(I13:K13) -> 0 | N13: 10 | P13: ='2'!Q13 -> 0 | R13: =Q13-P13 -> 0 | S13: 10 | T13: =R13*S13 -> 0
A14: ='1'!A14:B14 -> VidaPay | D14: ='1'!D14:E14 -> Cash Deposit | H14: TOTAL | I14: =SUM(I6:I13) -> 14428.59 | J14: =SUM(J6:J13) -> 326.5 | K14: =SUM(K6:K13) -> 0 | L14: =SUM(L6:M13) -> 14755.09 | N14: 11 | P14: ='2'!Q14 -> 0 | R14: =Q14-P14 -> 0 | S14: 5 | T14: =R14*S14 -> 0
A15: ='1'!A15:B15 -> Boost Epay | D15: ='1'!D15:E15 -> Money Gram Payment | N15: 12 | P15: ='2'!Q15 -> 0 | R15: =Q15-P15 -> 0 | S15: 5 | T15: =R15*S15 -> 0
A16: ='1'!A16:B16 -> Epay | D16: ='1'!D16:E16 -> Vigo Payment | N16: 13 | P16: ='2'!Q16 -> 0 | R16: =Q16-P16 -> 0 | S16: 5 | T16: =R16*S16 -> 0
A17: ='1'!A17:B17 -> Check Cashing Fees | C17: 336.23 | D17: ='1'!D17:E17 -> Ria Payment | N17: 14 | P17: ='2'!Q17 -> 0 | R17: =Q17-P17 -> 0 | S17: 5 | T17: =R17*S17 -> 0
A18: ='1'!A18:B18 -> Money Order | C18: 6003.17 | D18: ='1'!D18:E18 -> Checks Deposit | F18: =J25 -> 47013.95 | H18: CHECK DEPOSITS | K18: DROPS | L18: AMOUNT | M18: TIME | N18: 15 | P18: ='2'!Q18 -> 0 | R18: =Q18-P18 -> 0 | S18: 5 | T18: =R18*S18 -> 0
A19: ='1'!A19:B19 -> Return Check Paid | C19: =F33 -> 0 | D19: ='1'!D19:E19 -> Safe Balance | F19: 48991 | H19: CHECK DEPOSITS TO BANK | J19: AMOUNT | K19: 1 | L19: 3850 | M19: 0.55347222 | N19: 16 | P19: ='2'!Q19 -> 0 | R19: =Q19-P19 -> 0 | S19: 5 | T19: =R19*S19 -> 0
A20: ='1'!A20:B20 -> Forward Balance | C20: ='2'!F19+'2'!F13 -> 73871 | D20: ='1'!D20:E20 -> Payroll Expense | F20: =J40 -> 0 | H20: NIZARI | J20: 47013.95 | K20: 2 | L20: 5630 | M20: 0.625 | N20: 17 | P20: ='2'!Q20 -> 0 | R20: =Q20-P20 -> 0 | S20: 5 | T20: =R20*S20 -> 0
A21: ='1'!A21:B21 -> Cash From Bank | C21: 36000 | D21: ='1'!D21:E21 -> Other Cash Out | F21: =M53 -> 20231 | K21: 3 | L21: 2040 | M21: 0.83055556 | N21: 18 | P21: ='2'!Q21 -> 0 | R21: =Q21-P21 -> 0 | S21: 5 | T21: =R21*S21 -> 0
A22: ='1'!A22:B22 -> Other Cash In | C22: =J53 -> 0 | D22: TOTAL PAYOUTS | F22: =SUM(F5:F21)-F7-F8 -> 130990.95 | K22: 4 | L22: 2040 | M22: 0.83263889 | N22: 19 | P22: ='2'!Q22 -> 0 | R22: =Q22-P22 -> 0 | S22: 5 | T22: =R22*S22 -> 0
A23: ='1'!A23:B23 -> Rebates & Commissions | C23: =F53 -> 0 | D23: Inside Over - (Short) | F23: =(F11+F14+F15+F16+F17+F18+F19+F20+F21+F5+F6)-(C17+C19+C20+C21+C22+C23) -> 6028.72 | K23: 5 | L23: 1195 | M23: 0.875 | N23: 20 | P23: ='2'!Q23 -> 0 | R23: =Q23-P23 -> 0 | S23: 5 | T23: =R23*S23 -> 0
A24: TOTAL RECEIPTS | C24: =SUM(C5:C23) -> 130990.49 | D24: Over All Over - (Short) | F24: =SUM(F22-C24) -> 0.46 | K24: 6 | N24: 21 | P24: ='2'!Q24 -> 0 | R24: =Q24-P24 -> 0 | S24: 5 | T24: =R24*S24 -> 0
A25: Out Side Over - (Short) | C25: =(F9+F10+F12+F13)-(C5+C6+C7+C8+C9+C10+C11+C12+C13+C14+C15+C16+C18) -> -6028.26 | H25: TOTAL | J25: =SUM(J20:J24) -> 47013.95 | K25: 7 | N25: 22 | P25: ='2'!Q25 -> 0 | R25: =Q25-P25 -> 0 | S25: 5 | T25: =R25*S25 -> 0
A26: Cash Purchases | D26: Return Check Paid | K26: 8 | N26: 23 | P26: ='2'!Q26 -> 0 | R26: =Q26-P26 -> 0 | S26: 3 | T26: =R26*S26 -> 0
A27: Description | C27: Amount | D27: Description | F27: Amount | K27: 9 | N27: 24 | P27: ='2'!Q27 -> 0 | R27: =Q27-P27 -> 0 | S27: 3 | T27: =R27*S27 -> 0
H28: CASH PAYROLL EXPENSE | K28: 10 | N28: 25 | P28: ='2'!Q28 -> 0 | R28: =Q28-P28 -> 0 | S28: 2 | T28: =R28*S28 -> 0
H29: CASH PAYROLL PAID TO | J29: AMOUNT | K29: 11 | N29: 26 | P29: ='2'!Q29 -> 0 | R29: =Q29-P29 -> 0 | S29: 5 | T29: =R29*S29 -> 0
K30: 12 | N30: 27 | P30: ='2'!Q30 -> 0 | R30: =Q30-P30 -> 0 | S30: 3 | T30: =R30*S30 -> 0
K31: 13 | N31: 28 | P31: ='2'!Q31 -> 0 | R31: =Q31-P31 -> 0 | S31: 3 | T31: =R31*S31 -> 0
K32: 14 | N32: 29 | P32: ='2'!Q32 -> 0 | R32: =Q32-P32 -> 0 | S32: 2 | T32: =R32*S32 -> 0
D33: Total | F33: =SUM(F28:F32) -> 0 | K33: 15 | N33: 30 | P33: ='2'!Q33 -> 0 | R33: =Q33-P33 -> 0 | S33: 2 | T33: =R33*S33 -> 0
D34: Cash Expense | K34: 16 | N34: 31 | P34: ='2'!Q34 -> 0 | R34: =Q34-P34 -> 0 | S34: 2 | T34: =R34*S34 -> 0
D35: Description | F35: Amount | K35: 17 | N35: 32 | P35: ='2'!Q35 -> 0 | R35: =Q35-P35 -> 0 | S35: 2 | T35: =R35*S35 -> 0
K36: 18 | N36: 33 | P36: ='2'!Q36 -> 0 | R36: =Q36-P36 -> 0 | S36: 2 | T36: =R36*S36 -> 0
K37: 19 | N37: 34 | P37: ='2'!Q37 -> 0 | R37: =Q37-P37 -> 0 | S37: 1 | T37: =R37*S37 -> 0
K38: 20 | N38: 35 | P38: ='2'!Q38 -> 0 | R38: =Q38-P38 -> 0 | S38: 1 | T38: =R38*S38 -> 0
K39: 21 | N39: 36 | P39: ='2'!Q39 -> 0 | R39: =Q39-P39 -> 0 | S39: 2 | T39: =R39*S39 -> 0
A40: Total | C40: =SUM(C28:C39) -> 0 | D40: Total | F40: =SUM(F36:F39) -> 0 | H40: TOTAL | J40: =SUM(J30:J39) -> 0 | K40: TOTAL | L40: =SUM(L19:L39) -> 14755 | N40: 37 | P40: ='2'!Q40 -> 0 | R40: =Q40-P40 -> 0 | S40: 2 | T40: =R40*S40 -> 0
...

Sheet 4
A1: ='1'!A1:F1 -> DINERO EXPRESS #8 (512) 8015655 | H1: =A1 -> DINERO EXPRESS #8 (512) 8015655 | M1: DATE
A2: Daily Report | D2: Date: | F2: ='3'!F2+1 -> 3 | H2: OTHER REPORTS | M2: =F2 -> 3 | O2: Lottery Sale
D3: Day: | M3: =F3 -> 0 | O3: Game # | P3: Open | Q3: Close | R3: Tic.Sold | S3: $ Value | T3: T. Sale
A4: Reciepts | C4: Amount | D4: Disbursments | F4: Amount | H4: MONEY TRANSFER | N4: 1 | P4: ='3'!Q4 -> 0 | R4: =Q4-P4 -> 0 | S4: 50 | T4: =R4*S4 -> 0
A5: ='1'!A5:B5 -> Taxable Sale | C5: 10 | D5: ='1'!D5:E5 -> Cash Purchases | F5: =C40 -> 0 | H5: Company | I5: Amount | J5: Fees | K5: Commission | L5: Individual Total Amount | N5: 2 | P5: ='3'!Q5 -> 0 | R5: =Q5-P5 -> 0 | S5: 20 | T5: =R5*S5 -> 0
A6: ='1'!A6:B6 -> Comm & Fee | C6: 18 | D6: ='1'!D6:E6 -> Cash Expense | F6: =F40 -> 0 | H6: ='1'!H6 -> DINEX | L6: =SUM(I6:K6) -> 0 | N6: 3 | P6: ='3'!Q6 -> 0 | R6: =Q6-P6 -> 0 | S6: 20 | T6: =R6*S6 -> 0
A7: ='1'!A7:B7 -> Sales Tax | D7: ='1'!D7:E7 -> Check Purchases | F7: =C53 -> 0 | H7: ='1'!H7 -> INTERMEX | I7: 4559.68 | J7: 127 | L7: =SUM(I7:K7) -> 4686.68 | N7: 4 | P7: ='3'!Q7 -> 0 | R7: =Q7-P7 -> 0 | S7: 10 | T7: =R7*S7 -> 0
A8: ='1'!A8:B8 -> Money Transfers | C8: =L14 -> 9691.78 | D8: ='1'!D8:E8 -> Check Expense | F8: =F47 -> 0 | H8: ='1'!H8 -> SIGUE | L8: =SUM(I8:K8) -> 0 | N8: 5 | P8: ='3'!Q8 -> 0 | R8: =Q8-P8 -> 0 | S8: 10 | T8: =R8*S8 -> 0
A9: ='1'!A9:B9 -> Lottery Sales | C9: =S52 -> 0 | D9: ='1'!D9:E9 -> Lotto Paid Out | H9: ='1'!H9 -> AFEX | L9: =SUM(I9:K9) -> 0 | N9: 6 | P9: ='3'!Q9 -> 0 | R9: =Q9-P9 -> 0 | S9: 20 | T9: =R9*S9 -> 0
A10: ='1'!A10:B10 -> Lotto Net Sales | D10: ='1'!D10:E10 -> Lottery Paid Out | H10: ='1'!H10 -> MONEYGRAM | L10: =SUM(I10:K10) -> 0 | N10: 7 | P10: ='3'!Q10 -> 0 | R10: =Q10-P10 -> 0 | S10: 20 | T10: =R10*S10 -> 0
A11: ='1'!A11:B11 -> PhoneCard | D11: ='1'!D11:E11 -> ATM Drop | H11: ='1'!H11 -> BARRI | I11: 1093 | J11: 30 | L11: =SUM(I11:K11) -> 1123 | N11: 8 | P11: ='3'!Q11 -> 0 | R11: =Q11-P11 -> 0 | S11: 20 | T11: =R11*S11 -> 0
A12: ='1'!A12:B12 -> Boss Revolution | D12: ='1'!D12:E12 -> Credit Card | H12: ='1'!H12 -> MAXI | I12: 3769.1 | J12: 113 | L12: =SUM(I12:K12) -> 3882.1 | N12: 9 | P12: ='3'!Q12 -> 0 | R12: =Q12-P12 -> 0 | S12: 10 | T12: =R12*S12 -> 0
A13: ='1'!A13:B13 -> Bill Payment | D13: ='1'!D13:E13 -> Outside Cash & Drops | F13: =L40 -> 9596 | H13: ='1'!H13 -> AMIGO SIN PIN | L13: =SUM(I13:K13) -> 0 | N13: 10 | P13: ='3'!Q13 -> 0 | R13: =Q13-P13 -> 0 | S13: 10 | T13: =R13*S13 -> 0
A14: ='1'!A14:B14 -> VidaPay | D14: ='1'!D14:E14 -> Cash Deposit | H14: TOTAL | I14: =SUM(I6:I13) -> 9421.78 | J14: =SUM(J6:J13) -> 270 | K14: =SUM(K6:K13) -> 0 | L14: =SUM(L6:M13) -> 9691.78 | N14: 11 | P14: ='3'!Q14 -> 0 | R14: =Q14-P14 -> 0 | S14: 5 | T14: =R14*S14 -> 0
A15: ='1'!A15:B15 -> Boost Epay | D15: ='1'!D15:E15 -> Money Gram Payment | N15: 12 | P15: ='3'!Q15 -> 0 | R15: =Q15-P15 -> 0 | S15: 5 | T15: =R15*S15 -> 0
A16: ='1'!A16:B16 -> Epay | D16: ='1'!D16:E16 -> Vigo Payment | N16: 13 | P16: ='3'!Q16 -> 0 | R16: =Q16-P16 -> 0 | S16: 5 | T16: =R16*S16 -> 0
A17: ='1'!A17:B17 -> Check Cashing Fees | C17: 290.09 | D17: ='1'!D17:E17 -> Ria Payment | N17: 14 | P17: ='3'!Q17 -> 0 | R17: =Q17-P17 -> 0 | S17: 5 | T17: =R17*S17 -> 0
A18: ='1'!A18:B18 -> Money Order | C18: 4425 | D18: ='1'!D18:E18 -> Checks Deposit | F18: =J25 -> 49918.03 | H18: CHECK DEPOSITS | K18: DROPS | L18: AMOUNT | M18: TIME | N18: 15 | P18: ='3'!Q18 -> 0 | R18: =Q18-P18 -> 0 | S18: 5 | T18: =R18*S18 -> 0
A19: ='1'!A19:B19 -> Return Check Paid | C19: =F33 -> 0 | D19: ='1'!D19:E19 -> Safe Balance | F19: 54870 | H19: CHECK DEPOSITS TO BANK | J19: AMOUNT | K19: 1 | L19: 2850 | M19: 12:39PM | N19: 16 | P19: ='3'!Q19 -> 0 | R19: =Q19-P19 -> 0 | S19: 5 | T19: =R19*S19 -> 0
A20: ='1'!A20:B20 -> Forward Balance | C20: ='3'!F19+'3'!F13 -> 63746 | D20: ='1'!D20:E20 -> Payroll Expense | F20: =J40 -> 0 | H20: NIZARI (40 Checks) | J20: 49918.03 | K20: 2 | L20: 100 | M20: 1:37PM | N20: 17 | P20: ='3'!Q20 -> 0 | R20: =Q20-P20 -> 0 | S20: 5 | T20: =R20*S20 -> 0
A21: ='1'!A21:B21 -> Cash From Bank | C21: 43500 | D21: ='1'!D21:E21 -> Other Cash Out | F21: =M53 -> 8130 | K21: 3 | L21: 100 | M21: 1:37PM | N21: 18 | P21: ='3'!Q21 -> 0 | R21: =Q21-P21 -> 0 | S21: 5 | T21: =R21*S21 -> 0
A22: ='1'!A22:B22 -> Other Cash In | C22: =J53 -> 833 | D22: TOTAL PAYOUTS | F22: =SUM(F5:F21)-F7-F8 -> 122514.03 | K22: 4 | L22: 100 | M22: 1:37PM | N22: 19 | P22: ='3'!Q22 -> 0 | R22: =Q22-P22 -> 0 | S22: 5 | T22: =R22*S22 -> 0
A23: ='1'!A23:B23 -> Rebates & Commissions | C23: =F53 -> 0 | D23: Inside Over - (Short) | F23: =(F11+F14+F15+F16+F17+F18+F19+F20+F21+F5+F6)-(C17+C19+C20+C21+C22+C23) -> 4548.94 | K23: 5 | L23: 2490 | M23: 3:13PM | N23: 20 | P23: ='3'!Q23 -> 0 | R23: =Q23-P23 -> 0 | S23: 5 | T23: =R23*S23 -> 0
A24: TOTAL RECEIPTS | C24: =SUM(C5:C23) -> 122513.87 | D24: Over All Over - (Short) | F24: =SUM(F22-C24) -> 0.16 | K24: 6 | L24: 1690 | M24: 3:35PM | N24: 21 | P24: ='3'!Q24 -> 0 | R24: =Q24-P24 -> 0 | S24: 5 | T24: =R24*S24 -> 0
A25: Out Side Over - (Short) | C25: =(F9+F10+F12+F13)-(C5+C6+C7+C8+C9+C10+C11+C12+C13+C14+C15+C16+C18) -> -4548.78 | H25: TOTAL | J25: =SUM(J20:J24) -> 49918.03 | K25: 7 | L25: 2266 | M25: 8:34PM | N25: 22 | P25: ='3'!Q25 -> 0 | R25: =Q25-P25 -> 0 | S25: 5 | T25: =R25*S25 -> 0
A26: Cash Purchases | D26: Return Check Paid | K26: 8 | N26: 23 | P26: ='3'!Q26 -> 0 | R26: =Q26-P26 -> 0 | S26: 3 | T26: =R26*S26 -> 0
A27: Description | C27: Amount | D27: Description | F27: Amount | K27: 9 | N27: 24 | P27: ='3'!Q27 -> 0 | R27: =Q27-P27 -> 0 | S27: 3 | T27: =R27*S27 -> 0
H28: CASH PAYROLL EXPENSE | K28: 10 | N28: 25 | P28: ='3'!Q28 -> 0 | R28: =Q28-P28 -> 0 | S28: 2 | T28: =R28*S28 -> 0
H29: CASH PAYROLL PAID TO | J29: AMOUNT | K29: 11 | N29: 26 | P29: ='3'!Q29 -> 0 | R29: =Q29-P29 -> 0 | S29: 5 | T29: =R29*S29 -> 0
K30: 12 | N30: 27 | P30: ='3'!Q30 -> 0 | R30: =Q30-P30 -> 0 | S30: 3 | T30: =R30*S30 -> 0
K31: 13 | N31: 28 | P31: ='3'!Q31 -> 0 | R31: =Q31-P31 -> 0 | S31: 3 | T31: =R31*S31 -> 0
K32: 14 | N32: 29 | P32: ='3'!Q32 -> 0 | R32: =Q32-P32 -> 0 | S32: 2 | T32: =R32*S32 -> 0
D33: Total | F33: =SUM(F28:F32) -> 0 | K33: 15 | N33: 30 | P33: ='3'!Q33 -> 0 | R33: =Q33-P33 -> 0 | S33: 2 | T33: =R33*S33 -> 0
D34: Cash Expense | K34: 16 | N34: 31 | P34: ='3'!Q34 -> 0 | R34: =Q34-P34 -> 0 | S34: 2 | T34: =R34*S34 -> 0
D35: Description | F35: Amount | K35: 17 | N35: 32 | P35: ='3'!Q35 -> 0 | R35: =Q35-P35 -> 0 | S35: 2 | T35: =R35*S35 -> 0
K36: 18 | N36: 33 | P36: ='3'!Q36 -> 0 | R36: =Q36-P36 -> 0 | S36: 2 | T36: =R36*S36 -> 0
K37: 19 | N37: 34 | P37: ='3'!Q37 -> 0 | R37: =Q37-P37 -> 0 | S37: 1 | T37: =R37*S37 -> 0
K38: 20 | N38: 35 | P38: ='3'!Q38 -> 0 | R38: =Q38-P38 -> 0 | S38: 1 | T38: =R38*S38 -> 0
K39: 21 | N39: 36 | P39: ='3'!Q39 -> 0 | R39: =Q39-P39 -> 0 | S39: 2 | T39: =R39*S39 -> 0
A40: Total | C40: =SUM(C28:C39) -> 0 | D40: Total | F40: =SUM(F36:F39) -> 0 | H40: TOTAL | J40: =SUM(J30:J39) -> 0 | K40: TOTAL | L40: =SUM(L19:L39) -> 9596 | N40: 37 | P40: ='3'!Q40 -> 0 | R40: =Q40-P40 -> 0 | S40: 2 | T40: =R40*S40 -> 0
...

Sheet 5
A1: ='1'!A1:F1 -> DINERO EXPRESS #8 (512) 8015655 | H1: =A1 -> DINERO EXPRESS #8 (512) 8015655 | M1: DATE
A2: Daily Report | D2: Date: | F2: ='4'!F2+1 -> 4 | H2: OTHER REPORTS | M2: =F2 -> 4 | O2: Lottery Sale
D3: Day: | M3: =F3 -> 0 | O3: Game # | P3: Open | Q3: Close | R3: Tic.Sold | S3: $ Value | T3: T. Sale
A4: Reciepts | C4: Amount | D4: Disbursments | F4: Amount | H4: MONEY TRANSFER | N4: 1 | P4: ='4'!Q4 -> 0 | R4: =Q4-P4 -> 0 | S4: 50 | T4: =R4*S4 -> 0
A5: ='1'!A5:B5 -> Taxable Sale | C5: 36 | D5: ='1'!D5:E5 -> Cash Purchases | F5: =C40 -> 0 | H5: Company | I5: Amount | J5: Fees | K5: Commission | L5: Individual Total Amount | N5: 2 | P5: ='4'!Q5 -> 0 | R5: =Q5-P5 -> 0 | S5: 20 | T5: =R5*S5 -> 0
A6: ='1'!A6:B6 -> Comm & Fee | C6: 17 | D6: ='1'!D6:E6 -> Cash Expense | F6: =F40 -> 0 | H6: ='1'!H6 -> DINEX | L6: =SUM(I6:K6) -> 0 | N6: 3 | P6: ='4'!Q6 -> 0 | R6: =Q6-P6 -> 0 | S6: 20 | T6: =R6*S6 -> 0
A7: ='1'!A7:B7 -> Sales Tax | D7: ='1'!D7:E7 -> Check Purchases | F7: =C53 -> 0 | H7: ='1'!H7 -> INTERMEX | I7: 18292.7 | J7: 309.03 | L7: =SUM(I7:K7) -> 18601.73 | N7: 4 | P7: ='4'!Q7 -> 0 | R7: =Q7-P7 -> 0 | S7: 10 | T7: =R7*S7 -> 0
A8: ='1'!A8:B8 -> Money Transfers | C8: =L14 -> 23323.32 | D8: ='1'!D8:E8 -> Check Expense | F8: =F47 -> 0 | H8: ='1'!H8 -> SIGUE | L8: =SUM(I8:K8) -> 0 | N8: 5 | P8: ='4'!Q8 -> 0 | R8: =Q8-P8 -> 0 | S8: 10 | T8: =R8*S8 -> 0
A9: ='1'!A9:B9 -> Lottery Sales | C9: =S52 -> 0 | D9: ='1'!D9:E9 -> Lotto Paid Out | H9: ='1'!H9 -> AFEX | L9: =SUM(I9:K9) -> 0 | N9: 6 | P9: ='4'!Q9 -> 0 | R9: =Q9-P9 -> 0 | S9: 20 | T9: =R9*S9 -> 0
A10: ='1'!A10:B10 -> Lotto Net Sales | D10: ='1'!D10:E10 -> Lottery Paid Out | H10: ='1'!H10 -> MONEYGRAM | L10: =SUM(I10:K10) -> 0 | N10: 7 | P10: ='4'!Q10 -> 0 | R10: =Q10-P10 -> 0 | S10: 20 | T10: =R10*S10 -> 0
A11: ='1'!A11:B11 -> PhoneCard | D11: ='1'!D11:E11 -> ATM Drop | H11: ='1'!H11 -> BARRI | I11: 2095.75 | J11: 26 | L11: =SUM(I11:K11) -> 2121.75 | N11: 8 | P11: ='4'!Q11 -> 0 | R11: =Q11-P11 -> 0 | S11: 20 | T11: =R11*S11 -> 0
A12: ='1'!A12:B12 -> Boss Revolution | D12: ='1'!D12:E12 -> Credit Card | H12: ='1'!H12 -> MAXI | I12: 2535.84 | J12: 64 | L12: =SUM(I12:K12) -> 2599.84 | N12: 9 | P12: ='4'!Q12 -> 0 | R12: =Q12-P12 -> 0 | S12: 10 | T12: =R12*S12 -> 0
A13: ='1'!A13:B13 -> Bill Payment | D13: ='1'!D13:E13 -> Outside Cash & Drops | F13: =L40 -> 23327 | H13: ='1'!H13 -> AMIGO SIN PIN | L13: =SUM(I13:K13) -> 0 | N13: 10 | P13: ='4'!Q13 -> 0 | R13: =Q13-P13 -> 0 | S13: 10 | T13: =R13*S13 -> 0
A14: ='1'!A14:B14 -> VidaPay | D14: ='1'!D14:E14 -> Cash Deposit | H14: TOTAL | I14: =SUM(I6:I13) -> 22924.29 | J14: =SUM(J6:J13) -> 399.03 | K14: =SUM(K6:K13) -> 0 | L14: =SUM(L6:M13) -> 23323.32 | N14: 11 | P14: ='4'!Q14 -> 0 | R14: =Q14-P14 -> 0 | S14: 5 | T14: =R14*S14 -> 0
A15: ='1'!A15:B15 -> Boost Epay | D15: ='1'!D15:E15 -> Money Gram Payment | N15: 12 | P15: ='4'!Q15 -> 0 | R15: =Q15-P15 -> 0 | S15: 5 | T15: =R15*S15 -> 0
A16: ='1'!A16:B16 -> Epay | D16: ='1'!D16:E16 -> Vigo Payment | N16: 13 | P16: ='4'!Q16 -> 0 | R16: =Q16-P16 -> 0 | S16: 5 | T16: =R16*S16 -> 0
A17: ='1'!A17:B17 -> Check Cashing Fees | C17: 99.95 | D17: ='1'!D17:E17 -> Ria Payment | N17: 14 | P17: ='4'!Q17 -> 0 | R17: =Q17-P17 -> 0 | S17: 5 | T17: =R17*S17 -> 0
A18: ='1'!A18:B18 -> Money Order | C18: 3395 | D18: ='1'!D18:E18 -> Checks Deposit | F18: =J25 -> 23499.42 | H18: CHECK DEPOSITS | K18: DROPS | L18: AMOUNT | M18: TIME | N18: 15 | P18: ='4'!Q18 -> 0 | R18: =Q18-P18 -> 0 | S18: 5 | T18: =R18*S18 -> 0
A19: ='1'!A19:B19 -> Return Check Paid | C19: =F33 -> 0 | D19: ='1'!D19:E19 -> Safe Balance | F19: 47608 | H19: CHECK DEPOSITS TO BANK | J19: AMOUNT | K19: 1 | L19: 3000 | M19: 10:59AM | N19: 16 | P19: ='4'!Q19 -> 0 | R19: =Q19-P19 -> 0 | S19: 5 | T19: =R19*S19 -> 0
A20: ='1'!A20:B20 -> Forward Balance | C20: ='4'!F19+'4'!F13 -> 64466 | D20: ='1'!D20:E20 -> Payroll Expense | F20: =J40 -> 0 | H20: NIZARI (25 Checks) | J20: 23499.42 | K20: 2 | L20: 9850 | M20: 4:38PM | N20: 17 | P20: ='4'!Q20 -> 0 | R20: =Q20-P20 -> 0 | S20: 5 | T20: =R20*S20 -> 0
A21: ='1'!A21:B21 -> Cash From Bank | D21: ='1'!D21:E21 -> Other Cash Out | F21: =M53 -> 538 | K21: 3 | L21: 9941 | M21: 8:50PM | N21: 18 | P21: ='4'!Q21 -> 0 | R21: =Q21-P21 -> 0 | S21: 5 | T21: =R21*S21 -> 0
A22: ='1'!A22:B22 -> Other Cash In | C22: =J53 -> 3635 | D22: TOTAL PAYOUTS | F22: =SUM(F5:F21)-F7-F8 -> 94972.42 | K22: 4 | L22: 536 | M22: 9:02PM | N22: 19 | P22: ='4'!Q22 -> 0 | R22: =Q22-P22 -> 0 | S22: 5 | T22: =R22*S22 -> 0
A23: ='1'!A23:B23 -> Rebates & Commissions | C23: =F53 -> 0 | D23: Inside Over - (Short) | F23: =(F11+F14+F15+F16+F17+F18+F19+F20+F21+F5+F6)-(C17+C19+C20+C21+C22+C23) -> 3444.47 | K23: 5 | N23: 20 | P23: ='4'!Q23 -> 0 | R23: =Q23-P23 -> 0 | S23: 5 | T23: =R23*S23 -> 0
A24: TOTAL RECEIPTS | C24: =SUM(C5:C23) -> 94972.27 | D24: Over All Over - (Short) | F24: =SUM(F22-C24) -> 0.15 | K24: 6 | N24: 21 | P24: ='4'!Q24 -> 0 | R24: =Q24-P24 -> 0 | S24: 5 | T24: =R24*S24 -> 0
A25: Out Side Over - (Short) | C25: =(F9+F10+F12+F13)-(C5+C6+C7+C8+C9+C10+C11+C12+C13+C14+C15+C16+C18) -> -3444.32 | H25: TOTAL | J25: =SUM(J20:J24) -> 23499.42 | K25: 7 | N25: 22 | P25: ='4'!Q25 -> 0 | R25: =Q25-P25 -> 0 | S25: 5 | T25: =R25*S25 -> 0
A26: Cash Purchases | D26: Return Check Paid | K26: 8 | N26: 23 | P26: ='4'!Q26 -> 0 | R26: =Q26-P26 -> 0 | S26: 3 | T26: =R26*S26 -> 0
A27: Description | C27: Amount | D27: Description | F27: Amount | K27: 9 | N27: 24 | P27: ='4'!Q27 -> 0 | R27: =Q27-P27 -> 0 | S27: 3 | T27: =R27*S27 -> 0
H28: CASH PAYROLL EXPENSE | K28: 10 | N28: 25 | P28: ='4'!Q28 -> 0 | R28: =Q28-P28 -> 0 | S28: 2 | T28: =R28*S28 -> 0
H29: CASH PAYROLL PAID TO | J29: AMOUNT | K29: 11 | N29: 26 | P29: ='4'!Q29 -> 0 | R29: =Q29-P29 -> 0 | S29: 5 | T29: =R29*S29 -> 0
K30: 12 | N30: 27 | P30: ='4'!Q30 -> 0 | R30: =Q30-P30 -> 0 | S30: 3 | T30: =R30*S30 -> 0
K31: 13 | N31: 28 | P31: ='4'!Q31 -> 0 | R31: =Q31-P31 -> 0 | S31: 3 | T31: =R31*S31 -> 0
K32: 14 | N32: 29 | P32: ='4'!Q32 -> 0 | R32: =Q32-P32 -> 0 | S32: 2 | T32: =R32*S32 -> 0
D33: Total | F33: =SUM(F28:F32) -> 0 | K33: 15 | N33: 30 | P33: ='4'!Q33 -> 0 | R33: =Q33-P33 -> 0 | S33: 2 | T33: =R33*S33 -> 0
D34: Cash Expense | K34: 16 | N34: 31 | P34: ='4'!Q34 -> 0 | R34: =Q34-P34 -> 0 | S34: 2 | T34: =R34*S34 -> 0
D35: Description | F35: Amount | K35: 17 | N35: 32 | P35: ='4'!Q35 -> 0 | R35: =Q35-P35 -> 0 | S35: 2 | T35: =R35*S35 -> 0
K36: 18 | N36: 33 | P36: ='4'!Q36 -> 0 | R36: =Q36-P36 -> 0 | S36: 2 | T36: =R36*S36 -> 0
K37: 19 | N37: 34 | P37: ='4'!Q37 -> 0 | R37: =Q37-P37 -> 0 | S37: 1 | T37: =R37*S37 -> 0
K38: 20 | N38: 35 | P38: ='4'!Q38 -> 0 | R38: =Q38-P38 -> 0 | S38: 1 | T38: =R38*S38 -> 0
K39: 21 | N39: 36 | P39: ='4'!Q39 -> 0 | R39: =Q39-P39 -> 0 | S39: 2 | T39: =R39*S39 -> 0
A40: Total | C40: =SUM(C28:C39) -> 0 | D40: Total | F40: =SUM(F36:F39) -> 0 | H40: TOTAL | J40: =SUM(J30:J39) -> 0 | K40: TOTAL | L40: =SUM(L19:L39) -> 23327 | N40: 37 | P40: ='4'!Q40 -> 0 | R40: =Q40-P40 -> 0 | S40: 2 | T40: =R40*S40 -> 0
...

Sheet 6
A1: ='1'!A1:F1 -> DINERO EXPRESS #8 (512) 8015655 | H1: =A1 -> DINERO EXPRESS #8 (512) 8015655 | M1: DATE
A2: Daily Report | D2: Date: | F2: ='5'!F2+1 -> 5 | H2: OTHER REPORTS | M2: =F2 -> 5 | O2: Lottery Sale
D3: Day: | M3: =F3 -> 0 | O3: Game # | P3: Open | Q3: Close | R3: Tic.Sold | S3: $ Value | T3: T. Sale
A4: Reciepts | C4: Amount | D4: Disbursments | F4: Amount | H4: MONEY TRANSFER | N4: 1 | P4: ='5'!Q4 -> 0 | R4: =Q4-P4 -> 0 | S4: 50 | T4: =R4*S4 -> 0
A5: ='1'!A5:B5 -> Taxable Sale | C5: 32 | D5: ='1'!D5:E5 -> Cash Purchases | F5: =C40 -> 0 | H5: Company | I5: Amount | J5: Fees | K5: Commission | L5: Individual Total Amount | N5: 2 | P5: ='5'!Q5 -> 0 | R5: =Q5-P5 -> 0 | S5: 20 | T5: =R5*S5 -> 0
A6: ='1'!A6:B6 -> Comm & Fee | C6: 13 | D6: ='1'!D6:E6 -> Cash Expense | F6: =F40 -> 0 | H6: ='1'!H6 -> DINEX | L6: =SUM(I6:K6) -> 0 | N6: 3 | P6: ='5'!Q6 -> 0 | R6: =Q6-P6 -> 0 | S6: 20 | T6: =R6*S6 -> 0
A7: ='1'!A7:B7 -> Sales Tax | D7: ='1'!D7:E7 -> Check Purchases | F7: =C53 -> 0 | H7: ='1'!H7 -> INTERMEX | I7: 6209.8 | J7: 128 | L7: =SUM(I7:K7) -> 6337.8 | N7: 4 | P7: ='5'!Q7 -> 0 | R7: =Q7-P7 -> 0 | S7: 10 | T7: =R7*S7 -> 0
A8: ='1'!A8:B8 -> Money Transfers | C8: =L14 -> 9907.4 | D8: ='1'!D8:E8 -> Check Expense | F8: =F47 -> 0 | H8: ='1'!H8 -> SIGUE | L8: =SUM(I8:K8) -> 0 | N8: 5 | P8: ='5'!Q8 -> 0 | R8: =Q8-P8 -> 0 | S8: 10 | T8: =R8*S8 -> 0
A9: ='1'!A9:B9 -> Lottery Sales | C9: =S52 -> 0 | D9: ='1'!D9:E9 -> Lotto Paid Out | H9: ='1'!H9 -> AFEX | L9: =SUM(I9:K9) -> 0 | N9: 6 | P9: ='5'!Q9 -> 0 | R9: =Q9-P9 -> 0 | S9: 20 | T9: =R9*S9 -> 0
A10: ='1'!A10:B10 -> Lotto Net Sales | D10: ='1'!D10:E10 -> Lottery Paid Out | H10: ='1'!H10 -> MONEYGRAM | L10: =SUM(I10:K10) -> 0 | N10: 7 | P10: ='5'!Q10 -> 0 | R10: =Q10-P10 -> 0 | S10: 20 | T10: =R10*S10 -> 0
A11: ='1'!A11:B11 -> PhoneCard | D11: ='1'!D11:E11 -> ATM Drop | H11: ='1'!H11 -> BARRI | L11: =SUM(I11:K11) -> 0 | N11: 8 | P11: ='5'!Q11 -> 0 | R11: =Q11-P11 -> 0 | S11: 20 | T11: =R11*S11 -> 0
A12: ='1'!A12:B12 -> Boss Revolution | D12: ='1'!D12:E12 -> Credit Card | H12: ='1'!H12 -> MAXI | I12: 3417.6 | J12: 152 | L12: =SUM(I12:K12) -> 3569.6 | N12: 9 | P12: ='5'!Q12 -> 0 | R12: =Q12-P12 -> 0 | S12: 10 | T12: =R12*S12 -> 0
A13: ='1'!A13:B13 -> Bill Payment | D13: ='1'!D13:E13 -> Outside Cash & Drops | F13: =L40 -> 9908 | H13: ='1'!H13 -> AMIGO SIN PIN | L13: =SUM(I13:K13) -> 0 | N13: 10 | P13: ='5'!Q13 -> 0 | R13: =Q13-P13 -> 0 | S13: 10 | T13: =R13*S13 -> 0
A14: ='1'!A14:B14 -> VidaPay | D14: ='1'!D14:E14 -> Cash Deposit | H14: TOTAL | I14: =SUM(I6:I13) -> 9627.4 | J14: =SUM(J6:J13) -> 280 | K14: =SUM(K6:K13) -> 0 | L14: =SUM(L6:M13) -> 9907.4 | N14: 11 | P14: ='5'!Q14 -> 0 | R14: =Q14-P14 -> 0 | S14: 5 | T14: =R14*S14 -> 0
A15: ='1'!A15:B15 -> Boost Epay | D15: ='1'!D15:E15 -> Money Gram Payment | N15: 12 | P15: ='5'!Q15 -> 0 | R15: =Q15-P15 -> 0 | S15: 5 | T15: =R15*S15 -> 0
A16: ='1'!A16:B16 -> Epay | D16: ='1'!D16:E16 -> Vigo Payment | N16: 13 | P16: ='5'!Q16 -> 0 | R16: =Q16-P16 -> 0 | S16: 5 | T16: =R16*S16 -> 0
A17: ='1'!A17:B17 -> Check Cashing Fees | C17: 78.99 | D17: ='1'!D17:E17 -> Ria Payment | N17: 14 | P17: ='5'!Q17 -> 0 | R17: =Q17-P17 -> 0 | S17: 5 | T17: =R17*S17 -> 0
A18: ='1'!A18:B18 -> Money Order | C18: 4391 | D18: ='1'!D18:E18 -> Checks Deposit | F18: =J25 -> 13497.7 | H18: CHECK DEPOSITS | K18: DROPS | L18: AMOUNT | M18: TIME | N18: 15 | P18: ='5'!Q18 -> 0 | R18: =Q18-P18 -> 0 | S18: 5 | T18: =R18*S18 -> 0
A19: ='1'!A19:B19 -> Return Check Paid | C19: =F33 -> 550 | D19: ='1'!D19:E19 -> Safe Balance | F19: 62822 | H19: CHECK DEPOSITS TO BANK | J19: AMOUNT | K19: 1 | L19: 2160 | M19: 12:53PM | N19: 16 | P19: ='5'!Q19 -> 0 | R19: =Q19-P19 -> 0 | S19: 5 | T19: =R19*S19 -> 0
A20: ='1'!A20:B20 -> Forward Balance | C20: ='5'!F19+'5'!F13 -> 70935 | D20: ='1'!D20:E20 -> Payroll Expense | F20: =J40 -> 0 | H20: NIZARI (15 Checks) | J20: 13497.7 | K20: 2 | L20: 4790 | M20: 5:05PM | N20: 17 | P20: ='5'!Q20 -> 0 | R20: =Q20-P20 -> 0 | S20: 5 | T20: =R20*S20 -> 0
A21: ='1'!A21:B21 -> Cash From Bank | D21: ='1'!D21:E21 -> Other Cash Out | F21: =M53 -> 2300 | K21: 3 | L21: 2958 | M21: 8:52PM | N21: 18 | P21: ='5'!Q21 -> 0 | R21: =Q21-P21 -> 0 | S21: 5 | T21: =R21*S21 -> 0
A22: ='1'!A22:B22 -> Other Cash In | C22: =J53 -> 2620 | D22: TOTAL PAYOUTS | F22: =SUM(F5:F21)-F7-F8 -> 88527.7 | K22: 4 | N22: 19 | P22: ='5'!Q22 -> 0 | R22: =Q22-P22 -> 0 | S22: 5 | T22: =R22*S22 -> 0
A23: ='1'!A23:B23 -> Rebates & Commissions | C23: =F53 -> 0 | D23: Inside Over - (Short) | F23: =(F11+F14+F15+F16+F17+F18+F19+F20+F21+F5+F6)-(C17+C19+C20+C21+C22+C23) -> 4435.71 | K23: 5 | N23: 20 | P23: ='5'!Q23 -> 0 | R23: =Q23-P23 -> 0 | S23: 5 | T23: =R23*S23 -> 0
A24: TOTAL RECEIPTS | C24: =SUM(C5:C23) -> 88527.39 | D24: Over All Over - (Short) | F24: =SUM(F22-C24) -> 0.31 | K24: 6 | N24: 21 | P24: ='5'!Q24 -> 0 | R24: =Q24-P24 -> 0 | S24: 5 | T24: =R24*S24 -> 0
A25: Out Side Over - (Short) | C25: =(F9+F10+F12+F13)-(C5+C6+C7+C8+C9+C10+C11+C12+C13+C14+C15+C16+C18) -> -4435.4 | H25: TOTAL | J25: =SUM(J20:J24) -> 13497.7 | K25: 7 | N25: 22 | P25: ='5'!Q25 -> 0 | R25: =Q25-P25 -> 0 | S25: 5 | T25: =R25*S25 -> 0
A26: Cash Purchases | D26: Return Check Paid | K26: 8 | N26: 23 | P26: ='5'!Q26 -> 0 | R26: =Q26-P26 -> 0 | S26: 3 | T26: =R26*S26 -> 0
A27: Description | C27: Amount | D27: Description | F27: Amount | K27: 9 | N27: 24 | P27: ='5'!Q27 -> 0 | R27: =Q27-P27 -> 0 | S27: 3 | T27: =R27*S27 -> 0
D28: Innova Service | F28: 150 | H28: CASH PAYROLL EXPENSE | K28: 10 | N28: 25 | P28: ='5'!Q28 -> 0 | R28: =Q28-P28 -> 0 | S28: 2 | T28: =R28*S28 -> 0
D29: Santex (Partial Pay $400) | F29: 400 | H29: CASH PAYROLL PAID TO | J29: AMOUNT | K29: 11 | N29: 26 | P29: ='5'!Q29 -> 0 | R29: =Q29-P29 -> 0 | S29: 5 | T29: =R29*S29 -> 0
K30: 12 | N30: 27 | P30: ='5'!Q30 -> 0 | R30: =Q30-P30 -> 0 | S30: 3 | T30: =R30*S30 -> 0
K31: 13 | N31: 28 | P31: ='5'!Q31 -> 0 | R31: =Q31-P31 -> 0 | S31: 3 | T31: =R31*S31 -> 0
K32: 14 | N32: 29 | P32: ='5'!Q32 -> 0 | R32: =Q32-P32 -> 0 | S32: 2 | T32: =R32*S32 -> 0
D33: Total | F33: =SUM(F28:F32) -> 550 | K33: 15 | N33: 30 | P33: ='5'!Q33 -> 0 | R33: =Q33-P33 -> 0 | S33: 2 | T33: =R33*S33 -> 0
D34: Cash Expense | K34: 16 | N34: 31 | P34: ='5'!Q34 -> 0 | R34: =Q34-P34 -> 0 | S34: 2 | T34: =R34*S34 -> 0
D35: Description | F35: Amount | K35: 17 | N35: 32 | P35: ='5'!Q35 -> 0 | R35: =Q35-P35 -> 0 | S35: 2 | T35: =R35*S35 -> 0
K36: 18 | N36: 33 | P36: ='5'!Q36 -> 0 | R36: =Q36-P36 -> 0 | S36: 2 | T36: =R36*S36 -> 0
K37: 19 | N37: 34 | P37: ='5'!Q37 -> 0 | R37: =Q37-P37 -> 0 | S37: 1 | T37: =R37*S37 -> 0
K38: 20 | N38: 35 | P38: ='5'!Q38 -> 0 | R38: =Q38-P38 -> 0 | S38: 1 | T38: =R38*S38 -> 0
K39: 21 | N39: 36 | P39: ='5'!Q39 -> 0 | R39: =Q39-P39 -> 0 | S39: 2 | T39: =R39*S39 -> 0
A40: Total | C40: =SUM(C28:C39) -> 0 | D40: Total | F40: =SUM(F36:F39) -> 0 | H40: TOTAL | J40: =SUM(J30:J39) -> 0 | K40: TOTAL | L40: =SUM(L19:L39) -> 9908 | N40: 37 | P40: ='5'!Q40 -> 0 | R40: =Q40-P40 -> 0 | S40: 2 | T40: =R40*S40 -> 0
...

Sheet 7
A1: ='1'!A1:F1 -> DINERO EXPRESS #8 (512) 8015655 | H1: =A1 -> DINERO EXPRESS #8 (512) 8015655 | M1: DATE
A2: Daily Report | D2: Date: | F2: ='6'!F2+1 -> 6 | H2: OTHER REPORTS | M2: =F2 -> 6 | O2: Lottery Sale
D3: Day: | M3: =F3 -> 0 | O3: Game # | P3: Open | Q3: Close | R3: Tic.Sold | S3: $ Value | T3: T. Sale
A4: Reciepts | C4: Amount | D4: Disbursments | F4: Amount | H4: MONEY TRANSFER | N4: 1 | P4: ='6'!Q4 -> 0 | R4: =Q4-P4 -> 0 | S4: 50 | T4: =R4*S4 -> 0
A5: ='1'!A5:B5 -> Taxable Sale | C5: 19 | D5: ='1'!D5:E5 -> Cash Purchases | F5: =C40 -> 0 | H5: Company | I5: Amount | J5: Fees | K5: Commission | L5: Individual Total Amount | N5: 2 | P5: ='6'!Q5 -> 0 | R5: =Q5-P5 -> 0 | S5: 20 | T5: =R5*S5 -> 0
A6: ='1'!A6:B6 -> Comm & Fee | C6: 6 | D6: ='1'!D6:E6 -> Cash Expense | F6: =F40 -> 0 | H6: ='1'!H6 -> DINEX | L6: =SUM(I6:K6) -> 0 | N6: 3 | P6: ='6'!Q6 -> 0 | R6: =Q6-P6 -> 0 | S6: 20 | T6: =R6*S6 -> 0
A7: ='1'!A7:B7 -> Sales Tax | D7: ='1'!D7:E7 -> Check Purchases | F7: =C53 -> 0 | H7: ='1'!H7 -> INTERMEX | I7: 4852.6 | J7: 91 | L7: =SUM(I7:K7) -> 4943.6 | N7: 4 | P7: ='6'!Q7 -> 0 | R7: =Q7-P7 -> 0 | S7: 10 | T7: =R7*S7 -> 0
A8: ='1'!A8:B8 -> Money Transfers | C8: =L14 -> 6814.53 | D8: ='1'!D8:E8 -> Check Expense | F8: =F47 -> 0 | H8: ='1'!H8 -> SIGUE | L8: =SUM(I8:K8) -> 0 | N8: 5 | P8: ='6'!Q8 -> 0 | R8: =Q8-P8 -> 0 | S8: 10 | T8: =R8*S8 -> 0
A9: ='1'!A9:B9 -> Lottery Sales | C9: =S52 -> 0 | D9: ='1'!D9:E9 -> Lotto Paid Out | H9: ='1'!H9 -> AFEX | L9: =SUM(I9:K9) -> 0 | N9: 6 | P9: ='6'!Q9 -> 0 | R9: =Q9-P9 -> 0 | S9: 20 | T9: =R9*S9 -> 0
A10: ='1'!A10:B10 -> Lotto Net Sales | D10: ='1'!D10:E10 -> Lottery Paid Out | H10: ='1'!H10 -> MONEYGRAM | L10: =SUM(I10:K10) -> 0 | N10: 7 | P10: ='6'!Q10 -> 0 | R10: =Q10-P10 -> 0 | S10: 20 | T10: =R10*S10 -> 0
A11: ='1'!A11:B11 -> PhoneCard | D11: ='1'!D11:E11 -> ATM Drop | H11: ='1'!H11 -> BARRI | L11: =SUM(I11:K11) -> 0 | N11: 8 | P11: ='6'!Q11 -> 0 | R11: =Q11-P11 -> 0 | S11: 20 | T11: =R11*S11 -> 0
A12: ='1'!A12:B12 -> Boss Revolution | D12: ='1'!D12:E12 -> Credit Card | H12: ='1'!H12 -> MAXI | I12: 1810.93 | J12: 60 | L12: =SUM(I12:K12) -> 1870.93 | N12: 9 | P12: ='6'!Q12 -> 0 | R12: =Q12-P12 -> 0 | S12: 10 | T12: =R12*S12 -> 0
A13: ='1'!A13:B13 -> Bill Payment | D13: ='1'!D13:E13 -> Outside Cash & Drops | F13: =L40 -> 6926 | H13: ='1'!H13 -> AMIGO SIN PIN | L13: =SUM(I13:K13) -> 0 | N13: 10 | P13: ='6'!Q13 -> 0 | R13: =Q13-P13 -> 0 | S13: 10 | T13: =R13*S13 -> 0
A14: ='1'!A14:B14 -> VidaPay | D14: ='1'!D14:E14 -> Cash Deposit | H14: TOTAL | I14: =SUM(I6:I13) -> 6663.53 | J14: =SUM(J6:J13) -> 151 | K14: =SUM(K6:K13) -> 0 | L14: =SUM(L6:M13) -> 6814.53 | N14: 11 | P14: ='6'!Q14 -> 0 | R14: =Q14-P14 -> 0 | S14: 5 | T14: =R14*S14 -> 0
A15: ='1'!A15:B15 -> Boost Epay | D15: ='1'!D15:E15 -> Money Gram Payment | N15: 12 | P15: ='6'!Q15 -> 0 | R15: =Q15-P15 -> 0 | S15: 5 | T15: =R15*S15 -> 0
A16: ='1'!A16:B16 -> Epay | D16: ='1'!D16:E16 -> Vigo Payment | N16: 13 | P16: ='6'!Q16 -> 0 | R16: =Q16-P16 -> 0 | S16: 5 | T16: =R16*S16 -> 0
A17: ='1'!A17:B17 -> Check Cashing Fees | C17: 162.79 | D17: ='1'!D17:E17 -> Ria Payment | N17: 14 | P17: ='6'!Q17 -> 0 | R17: =Q17-P17 -> 0 | S17: 5 | T17: =R17*S17 -> 0
A18: ='1'!A18:B18 -> Money Order | C18: 750 | D18: ='1'!D18:E18 -> Checks Deposit | F18: =J25 -> 32558.48 | H18: CHECK DEPOSITS | K18: DROPS | L18: AMOUNT | M18: TIME | N18: 15 | P18: ='6'!Q18 -> 0 | R18: =Q18-P18 -> 0 | S18: 5 | T18: =R18*S18 -> 0
A19: ='1'!A19:B19 -> Return Check Paid | C19: =F33 -> 0 | D19: ='1'!D19:E19 -> Safe Balance | F19: 66804 | H19: CHECK DEPOSITS TO BANK | J19: AMOUNT | K19: 1 | L19: 3040 | M19: 4:03PM | N19: 16 | P19: ='6'!Q19 -> 0 | R19: =Q19-P19 -> 0 | S19: 5 | T19: =R19*S19 -> 0
A20: ='1'!A20:B20 -> Forward Balance | C20: ='6'!F19+'6'!F13 -> 72730 | D20: ='1'!D20:E20 -> Payroll Expense | F20: =J40 -> 0 | H20: NIZARI (22 Checks) | J20: 32558.48 | K20: 2 | L20: 3395 | M20: 8:10PM | N20: 17 | P20: ='6'!Q20 -> 0 | R20: =Q20-P20 -> 0 | S20: 5 | T20: =R20*S20 -> 0
A21: ='1'!A21:B21 -> Cash From Bank | C21: 25500 | D21: ='1'!D21:E21 -> Other Cash Out | F21: =M53 -> 20 | K21: 3 | L21: 471 | M21: 8:49PM | N21: 18 | P21: ='6'!Q21 -> 0 | R21: =Q21-P21 -> 0 | S21: 5 | T21: =R21*S21 -> 0
A22: ='1'!A22:B22 -> Other Cash In | C22: =J53 -> 326 | D22: TOTAL PAYOUTS | F22: =SUM(F5:F21)-F7-F8 -> 106308.48 | K22: 4 | L22: 20 | N22: 19 | P22: ='6'!Q22 -> 0 | R22: =Q22-P22 -> 0 | S22: 5 | T22: =R22*S22 -> 0
A23: ='1'!A23:B23 -> Rebates & Commissions | C23: =F53 -> 0 | D23: Inside Over - (Short) | F23: =(F11+F14+F15+F16+F17+F18+F19+F20+F21+F5+F6)-(C17+C19+C20+C21+C22+C23) -> 663.69 | K23: 5 | N23: 20 | P23: ='6'!Q23 -> 0 | R23: =Q23-P23 -> 0 | S23: 5 | T23: =R23*S23 -> 0
A24: TOTAL RECEIPTS | C24: =SUM(C5:C23) -> 106308.32 | D24: Over All Over - (Short) | F24: =SUM(F22-C24) -> 0.16 | K24: 6 | N24: 21 | P24: ='6'!Q24 -> 0 | R24: =Q24-P24 -> 0 | S24: 5 | T24: =R24*S24 -> 0
A25: Out Side Over - (Short) | C25: =(F9+F10+F12+F13)-(C5+C6+C7+C8+C9+C10+C11+C12+C13+C14+C15+C16+C18) -> -663.53 | H25: TOTAL | J25: =SUM(J20:J24) -> 32558.48 | K25: 7 | N25: 22 | P25: ='6'!Q25 -> 0 | R25: =Q25-P25 -> 0 | S25: 5 | T25: =R25*S25 -> 0
A26: Cash Purchases | D26: Return Check Paid | K26: 8 | N26: 23 | P26: ='6'!Q26 -> 0 | R26: =Q26-P26 -> 0 | S26: 3 | T26: =R26*S26 -> 0
A27: Description | C27: Amount | D27: Description | F27: Amount | K27: 9 | N27: 24 | P27: ='6'!Q27 -> 0 | R27: =Q27-P27 -> 0 | S27: 3 | T27: =R27*S27 -> 0
H28: CASH PAYROLL EXPENSE | K28: 10 | N28: 25 | P28: ='6'!Q28 -> 0 | R28: =Q28-P28 -> 0 | S28: 2 | T28: =R28*S28 -> 0
H29: CASH PAYROLL PAID TO | J29: AMOUNT | K29: 11 | N29: 26 | P29: ='6'!Q29 -> 0 | R29: =Q29-P29 -> 0 | S29: 5 | T29: =R29*S29 -> 0
K30: 12 | N30: 27 | P30: ='6'!Q30 -> 0 | R30: =Q30-P30 -> 0 | S30: 3 | T30: =R30*S30 -> 0
K31: 13 | N31: 28 | P31: ='6'!Q31 -> 0 | R31: =Q31-P31 -> 0 | S31: 3 | T31: =R31*S31 -> 0
K32: 14 | N32: 29 | P32: ='6'!Q32 -> 0 | R32: =Q32-P32 -> 0 | S32: 2 | T32: =R32*S32 -> 0
D33: Total | F33: =SUM(F28:F32) -> 0 | K33: 15 | N33: 30 | P33: ='6'!Q33 -> 0 | R33: =Q33-P33 -> 0 | S33: 2 | T33: =R33*S33 -> 0
D34: Cash Expense | K34: 16 | N34: 31 | P34: ='6'!Q34 -> 0 | R34: =Q34-P34 -> 0 | S34: 2 | T34: =R34*S34 -> 0
D35: Description | F35: Amount | K35: 17 | N35: 32 | P35: ='6'!Q35 -> 0 | R35: =Q35-P35 -> 0 | S35: 2 | T35: =R35*S35 -> 0
K36: 18 | N36: 33 | P36: ='6'!Q36 -> 0 | R36: =Q36-P36 -> 0 | S36: 2 | T36: =R36*S36 -> 0
K37: 19 | N37: 34 | P37: ='6'!Q37 -> 0 | R37: =Q37-P37 -> 0 | S37: 1 | T37: =R37*S37 -> 0
K38: 20 | N38: 35 | P38: ='6'!Q38 -> 0 | R38: =Q38-P38 -> 0 | S38: 1 | T38: =R38*S38 -> 0
K39: 21 | N39: 36 | P39: ='6'!Q39 -> 0 | R39: =Q39-P39 -> 0 | S39: 2 | T39: =R39*S39 -> 0
A40: Total | C40: =SUM(C28:C39) -> 0 | D40: Total | F40: =SUM(F36:F39) -> 0 | H40: TOTAL | J40: =SUM(J30:J39) -> 0 | K40: TOTAL | L40: =SUM(L19:L39) -> 6926 | N40: 37 | P40: ='6'!Q40 -> 0 | R40: =Q40-P40 -> 0 | S40: 2 | T40: =R40*S40 -> 0
...

Sheet 8
A1: ='1'!A1:F1 -> DINERO EXPRESS #8 (512) 8015655 | H1: =A1 -> DINERO EXPRESS #8 (512) 8015655 | M1: DATE
A2: Daily Report | D2: Date: | F2: ='7'!F2+1 -> 7 | H2: OTHER REPORTS | M2: =F2 -> 7 | O2: Lottery Sale
D3: Day: | M3: =F3 -> 0 | O3: Game # | P3: Open | Q3: Close | R3: Tic.Sold | S3: $ Value | T3: T. Sale
A4: Reciepts | C4: Amount | D4: Disbursments | F4: Amount | H4: MONEY TRANSFER | N4: 1 | P4: ='7'!Q4 -> 0 | R4: =Q4-P4 -> 0 | S4: 50 | T4: =R4*S4 -> 0
A5: ='1'!A5:B5 -> Taxable Sale | C5: 6 | D5: ='1'!D5:E5 -> Cash Purchases | F5: =C40 -> 0 | H5: Company | I5: Amount | J5: Fees | K5: Commission | L5: Individual Total Amount | N5: 2 | P5: ='7'!Q5 -> 0 | R5: =Q5-P5 -> 0 | S5: 20 | T5: =R5*S5 -> 0
A6: ='1'!A6:B6 -> Comm & Fee | C6: 9 | D6: ='1'!D6:E6 -> Cash Expense | F6: =F40 -> 0 | H6: ='1'!H6 -> DINEX | L6: =SUM(I6:K6) -> 0 | N6: 3 | P6: ='7'!Q6 -> 0 | R6: =Q6-P6 -> 0 | S6: 20 | T6: =R6*S6 -> 0
A7: ='1'!A7:B7 -> Sales Tax | D7: ='1'!D7:E7 -> Check Purchases | F7: =C53 -> 0 | H7: ='1'!H7 -> INTERMEX | I7: 1883 | J7: 51 | L7: =SUM(I7:K7) -> 1934 | N7: 4 | P7: ='7'!Q7 -> 0 | R7: =Q7-P7 -> 0 | S7: 10 | T7: =R7*S7 -> 0
A8: ='1'!A8:B8 -> Money Transfers | C8: =L14 -> 6765.8 | D8: ='1'!D8:E8 -> Check Expense | F8: =F47 -> 0 | H8: ='1'!H8 -> SIGUE | L8: =SUM(I8:K8) -> 0 | N8: 5 | P8: ='7'!Q8 -> 0 | R8: =Q8-P8 -> 0 | S8: 10 | T8: =R8*S8 -> 0
A9: ='1'!A9:B9 -> Lottery Sales | C9: =S52 -> 0 | D9: ='1'!D9:E9 -> Lotto Paid Out | H9: ='1'!H9 -> AFEX | L9: =SUM(I9:K9) -> 0 | N9: 6 | P9: ='7'!Q9 -> 0 | R9: =Q9-P9 -> 0 | S9: 20 | T9: =R9*S9 -> 0
A10: ='1'!A10:B10 -> Lotto Net Sales | D10: ='1'!D10:E10 -> Lottery Paid Out | H10: ='1'!H10 -> MONEYGRAM | L10: =SUM(I10:K10) -> 0 | N10: 7 | P10: ='7'!Q10 -> 0 | R10: =Q10-P10 -> 0 | S10: 20 | T10: =R10*S10 -> 0
A11: ='1'!A11:B11 -> PhoneCard | D11: ='1'!D11:E11 -> ATM Drop | H11: ='1'!H11 -> BARRI | I11: 1702 | J11: 30 | L11: =SUM(I11:K11) -> 1732 | N11: 8 | P11: ='7'!Q11 -> 0 | R11: =Q11-P11 -> 0 | S11: 20 | T11: =R11*S11 -> 0
A12: ='1'!A12:B12 -> Boss Revolution | D12: ='1'!D12:E12 -> Credit Card | H12: ='1'!H12 -> MAXI | I12: 3027.8 | J12: 72 | L12: =SUM(I12:K12) -> 3099.8 | N12: 9 | P12: ='7'!Q12 -> 0 | R12: =Q12-P12 -> 0 | S12: 10 | T12: =R12*S12 -> 0
A13: ='1'!A13:B13 -> Bill Payment | D13: ='1'!D13:E13 -> Outside Cash & Drops | F13: =L40 -> 6660 | H13: ='1'!H13 -> AMIGO SIN PIN | L13: =SUM(I13:K13) -> 0 | N13: 10 | P13: ='7'!Q13 -> 0 | R13: =Q13-P13 -> 0 | S13: 10 | T13: =R13*S13 -> 0
A14: ='1'!A14:B14 -> VidaPay | D14: ='1'!D14:E14 -> Cash Deposit | H14: TOTAL | I14: =SUM(I6:I13) -> 6612.8 | J14: =SUM(J6:J13) -> 153 | K14: =SUM(K6:K13) -> 0 | L14: =SUM(L6:M13) -> 6765.8 | N14: 11 | P14: ='7'!Q14 -> 0 | R14: =Q14-P14 -> 0 | S14: 5 | T14: =R14*S14 -> 0
A15: ='1'!A15:B15 -> Boost Epay | D15: ='1'!D15:E15 -> Money Gram Payment | N15: 12 | P15: ='7'!Q15 -> 0 | R15: =Q15-P15 -> 0 | S15: 5 | T15: =R15*S15 -> 0
A16: ='1'!A16:B16 -> Epay | D16: ='1'!D16:E16 -> Vigo Payment | N16: 13 | P16: ='7'!Q16 -> 0 | R16: =Q16-P16 -> 0 | S16: 5 | T16: =R16*S16 -> 0
A17: ='1'!A17:B17 -> Check Cashing Fees | C17: 165.58 | D17: ='1'!D17:E17 -> Ria Payment | N17: 14 | P17: ='7'!Q17 -> 0 | R17: =Q17-P17 -> 0 | S17: 5 | T17: =R17*S17 -> 0
A18: ='1'!A18:B18 -> Money Order | C18: 1335 | D18: ='1'!D18:E18 -> Checks Deposit | F18: =J25 -> 33116.3 | H18: CHECK DEPOSITS | K18: DROPS | L18: AMOUNT | M18: TIME | N18: 15 | P18: ='7'!Q18 -> 0 | R18: =Q18-P18 -> 0 | S18: 5 | T18: =R18*S18 -> 0
A19: ='1'!A19:B19 -> Return Check Paid | C19: =F33 -> 0 | D19: ='1'!D19:E19 -> Safe Balance | F19: 42579 | H19: CHECK DEPOSITS TO BANK | J19: AMOUNT | K19: 1 | L19: 1735 | M19: 3:00PM | N19: 16 | P19: ='7'!Q19 -> 0 | R19: =Q19-P19 -> 0 | S19: 5 | T19: =R19*S19 -> 0
A20: ='1'!A20:B20 -> Forward Balance | C20: ='7'!F19+'7'!F13 -> 73730 | D20: ='1'!D20:E20 -> Payroll Expense | F20: =J40 -> 0 | H20: NIZARI (25 Checks) | J20: 33116.3 | K20: 2 | L20: 4597 | M20: 9:02PM | N20: 17 | P20: ='7'!Q20 -> 0 | R20: =Q20-P20 -> 0 | S20: 5 | T20: =R20*S20 -> 0
A21: ='1'!A21:B21 -> Cash From Bank | D21: ='1'!D21:E21 -> Other Cash Out | F21: =M53 -> 109 | K21: 3 | L21: 328 | M21: Pending | N21: 18 | P21: ='7'!Q21 -> 0 | R21: =Q21-P21 -> 0 | S21: 5 | T21: =R21*S21 -> 0
A22: ='1'!A22:B22 -> Other Cash In | C22: =J53 -> 452 | D22: TOTAL PAYOUTS | F22: =SUM(F5:F21)-F7-F8 -> 82464.3 | K22: 4 | N22: 19 | P22: ='7'!Q22 -> 0 | R22: =Q22-P22 -> 0 | S22: 5 | T22: =R22*S22 -> 0
A23: ='1'!A23:B23 -> Rebates & Commissions | C23: =F53 -> 0 | D23: Inside Over - (Short) | F23: =(F11+F14+F15+F16+F17+F18+F19+F20+F21+F5+F6)-(C17+C19+C20+C21+C22+C23) -> 1456.72 | K23: 5 | N23: 20 | P23: ='7'!Q23 -> 0 | R23: =Q23-P23 -> 0 | S23: 5 | T23: =R23*S23 -> 0
A24: TOTAL RECEIPTS | C24: =SUM(C5:C23) -> 82463.38 | D24: Over All Over - (Short) | F24: =SUM(F22-C24) -> 0.92 | K24: 6 | N24: 21 | P24: ='7'!Q24 -> 0 | R24: =Q24-P24 -> 0 | S24: 5 | T24: =R24*S24 -> 0
A25: Out Side Over - (Short) | C25: =(F9+F10+F12+F13)-(C5+C6+C7+C8+C9+C10+C11+C12+C13+C14+C15+C16+C18) -> -1455.8 | H25: TOTAL | J25: =SUM(J20:J24) -> 33116.3 | K25: 7 | N25: 22 | P25: ='7'!Q25 -> 0 | R25: =Q25-P25 -> 0 | S25: 5 | T25: =R25*S25 -> 0
A26: Cash Purchases | D26: Return Check Paid | K26: 8 | N26: 23 | P26: ='7'!Q26 -> 0 | R26: =Q26-P26 -> 0 | S26: 3 | T26: =R26*S26 -> 0
A27: Description | C27: Amount | D27: Description | F27: Amount | K27: 9 | N27: 24 | P27: ='7'!Q27 -> 0 | R27: =Q27-P27 -> 0 | S27: 3 | T27: =R27*S27 -> 0
H28: CASH PAYROLL EXPENSE | K28: 10 | N28: 25 | P28: ='7'!Q28 -> 0 | R28: =Q28-P28 -> 0 | S28: 2 | T28: =R28*S28 -> 0
H29: CASH PAYROLL PAID TO | J29: AMOUNT | K29: 11 | N29: 26 | P29: ='7'!Q29 -> 0 | R29: =Q29-P29 -> 0 | S29: 5 | T29: =R29*S29 -> 0
K30: 12 | N30: 27 | P30: ='7'!Q30 -> 0 | R30: =Q30-P30 -> 0 | S30: 3 | T30: =R30*S30 -> 0
K31: 13 | N31: 28 | P31: ='7'!Q31 -> 0 | R31: =Q31-P31 -> 0 | S31: 3 | T31: =R31*S31 -> 0
K32: 14 | N32: 29 | P32: ='7'!Q32 -> 0 | R32: =Q32-P32 -> 0 | S32: 2 | T32: =R32*S32 -> 0
D33: Total | F33: =SUM(F28:F32) -> 0 | K33: 15 | N33: 30 | P33: ='7'!Q33 -> 0 | R33: =Q33-P33 -> 0 | S33: 2 | T33: =R33*S33 -> 0
D34: Cash Expense | K34: 16 | N34: 31 | P34: ='7'!Q34 -> 0 | R34: =Q34-P34 -> 0 | S34: 2 | T34: =R34*S34 -> 0
D35: Description | F35: Amount | K35: 17 | N35: 32 | P35: ='7'!Q35 -> 0 | R35: =Q35-P35 -> 0 | S35: 2 | T35: =R35*S35 -> 0
K36: 18 | N36: 33 | P36: ='7'!Q36 -> 0 | R36: =Q36-P36 -> 0 | S36: 2 | T36: =R36*S36 -> 0
K37: 19 | N37: 34 | P37: ='7'!Q37 -> 0 | R37: =Q37-P37 -> 0 | S37: 1 | T37: =R37*S37 -> 0
K38: 20 | N38: 35 | P38: ='7'!Q38 -> 0 | R38: =Q38-P38 -> 0 | S38: 1 | T38: =R38*S38 -> 0
K39: 21 | N39: 36 | P39: ='7'!Q39 -> 0 | R39: =Q39-P39 -> 0 | S39: 2 | T39: =R39*S39 -> 0
A40: Total | C40: =SUM(C28:C39) -> 0 | D40: Total | F40: =SUM(F36:F39) -> 0 | H40: TOTAL | J40: =SUM(J30:J39) -> 0 | K40: TOTAL | L40: =SUM(L19:L39) -> 6660 | N40: 37 | P40: ='7'!Q40 -> 0 | R40: =Q40-P40 -> 0 | S40: 2 | T40: =R40*S40 -> 0
...

Sheet 9
A1: ='1'!A1:F1 -> DINERO EXPRESS #8 (512) 8015655 | H1: =A1 -> DINERO EXPRESS #8 (512) 8015655 | M1: DATE
A2: Daily Report | D2: Date: | F2: ='8'!F2+1 -> 8 | H2: OTHER REPORTS | M2: =F2 -> 8 | O2: Lottery Sale
D3: Day: | M3: =F3 -> 0 | O3: Game # | P3: Open | Q3: Close | R3: Tic.Sold | S3: $ Value | T3: T. Sale
A4: Reciepts | C4: Amount | D4: Disbursments | F4: Amount | H4: MONEY TRANSFER | N4: 1 | P4: ='8'!Q4 -> 0 | R4: =Q4-P4 -> 0 | S4: 50 | T4: =R4*S4 -> 0
A5: ='1'!A5:B5 -> Taxable Sale | C5: 14 | D5: ='1'!D5:E5 -> Cash Purchases | F5: =C40 -> 0 | H5: Company | I5: Amount | J5: Fees | K5: Commission | L5: Individual Total Amount | N5: 2 | P5: ='8'!Q5 -> 0 | R5: =Q5-P5 -> 0 | S5: 20 | T5: =R5*S5 -> 0
A6: ='1'!A6:B6 -> Comm & Fee | C6: 4 | D6: ='1'!D6:E6 -> Cash Expense | F6: =F40 -> 0 | H6: ='1'!H6 -> DINEX | L6: =SUM(I6:K6) -> 0 | N6: 3 | P6: ='8'!Q6 -> 0 | R6: =Q6-P6 -> 0 | S6: 20 | T6: =R6*S6 -> 0
A7: ='1'!A7:B7 -> Sales Tax | D7: ='1'!D7:E7 -> Check Purchases | F7: =C53 -> 0 | H7: ='1'!H7 -> INTERMEX | I7: 2095.01 | J7: 74 | L7: =SUM(I7:K7) -> 2169.01 | N7: 4 | P7: ='8'!Q7 -> 0 | R7: =Q7-P7 -> 0 | S7: 10 | T7: =R7*S7 -> 0
A8: ='1'!A8:B8 -> Money Transfers | C8: =L14 -> 7827.16 | D8: ='1'!D8:E8 -> Check Expense | F8: =F47 -> 0 | H8: ='1'!H8 -> SIGUE | L8: =SUM(I8:K8) -> 0 | N8: 5 | P8: ='8'!Q8 -> 0 | R8: =Q8-P8 -> 0 | S8: 10 | T8: =R8*S8 -> 0
A9: ='1'!A9:B9 -> Lottery Sales | C9: =S52 -> 0 | D9: ='1'!D9:E9 -> Lotto Paid Out | H9: ='1'!H9 -> AFEX | L9: =SUM(I9:K9) -> 0 | N9: 6 | P9: ='8'!Q9 -> 0 | R9: =Q9-P9 -> 0 | S9: 20 | T9: =R9*S9 -> 0
A10: ='1'!A10:B10 -> Lotto Net Sales | D10: ='1'!D10:E10 -> Lottery Paid Out | H10: ='1'!H10 -> MONEYGRAM | L10: =SUM(I10:K10) -> 0 | N10: 7 | P10: ='8'!Q10 -> 0 | R10: =Q10-P10 -> 0 | S10: 20 | T10: =R10*S10 -> 0
A11: ='1'!A11:B11 -> PhoneCard | D11: ='1'!D11:E11 -> ATM Drop | H11: ='1'!H11 -> BARRI | I11: 975.38 | J11: 44 | L11: =SUM(I11:K11) -> 1019.38 | N11: 8 | P11: ='8'!Q11 -> 0 | R11: =Q11-P11 -> 0 | S11: 20 | T11: =R11*S11 -> 0
A12: ='1'!A12:B12 -> Boss Revolution | D12: ='1'!D12:E12 -> Credit Card | H12: ='1'!H12 -> MAXI | I12: 4527.77 | J12: 111 | L12: =SUM(I12:K12) -> 4638.77 | N12: 9 | P12: ='8'!Q12 -> 0 | R12: =Q12-P12 -> 0 | S12: 10 | T12: =R12*S12 -> 0
A13: ='1'!A13:B13 -> Bill Payment | D13: ='1'!D13:E13 -> Outside Cash & Drops | F13: =L40 -> 7827 | H13: ='1'!H13 -> AMIGO SIN PIN | L13: =SUM(I13:K13) -> 0 | N13: 10 | P13: ='8'!Q13 -> 0 | R13: =Q13-P13 -> 0 | S13: 10 | T13: =R13*S13 -> 0
A14: ='1'!A14:B14 -> VidaPay | D14: ='1'!D14:E14 -> Cash Deposit | H14: TOTAL | I14: =SUM(I6:I13) -> 7598.16 | J14: =SUM(J6:J13) -> 229 | K14: =SUM(K6:K13) -> 0 | L14: =SUM(L6:M13) -> 7827.16 | N14: 11 | P14: ='8'!Q14 -> 0 | R14: =Q14-P14 -> 0 | S14: 5 | T14: =R14*S14 -> 0
A15: ='1'!A15:B15 -> Boost Epay | D15: ='1'!D15:E15 -> Money Gram Payment | N15: 12 | P15: ='8'!Q15 -> 0 | R15: =Q15-P15 -> 0 | S15: 5 | T15: =R15*S15 -> 0
A16: ='1'!A16:B16 -> Epay | D16: ='1'!D16:E16 -> Vigo Payment | N16: 13 | P16: ='8'!Q16 -> 0 | R16: =Q16-P16 -> 0 | S16: 5 | T16: =R16*S16 -> 0
A17: ='1'!A17:B17 -> Check Cashing Fees | C17: 116.44 | D17: ='1'!D17:E17 -> Ria Payment | N17: 14 | P17: ='8'!Q17 -> 0 | R17: =Q17-P17 -> 0 | S17: 5 | T17: =R17*S17 -> 0
A18: ='1'!A18:B18 -> Money Order | C18: 338 | D18: ='1'!D18:E18 -> Checks Deposit | F18: =J25 -> 23288.32 | H18: CHECK DEPOSITS | K18: DROPS | L18: AMOUNT | M18: TIME | N18: 15 | P18: ='8'!Q18 -> 0 | R18: =Q18-P18 -> 0 | S18: 5 | T18: =R18*S18 -> 0
A19: ='1'!A19:B19 -> Return Check Paid | C19: =F33 -> 620 | D19: ='1'!D19:E19 -> Safe Balance | F19: 47166 | H19: CHECK DEPOSITS TO BANK | J19: AMOUNT | K19: 1 | L19: 2500 | M19: 12:35PM | N19: 16 | P19: ='8'!Q19 -> 0 | R19: =Q19-P19 -> 0 | S19: 5 | T19: =R19*S19 -> 0
A20: ='1'!A20:B20 -> Forward Balance | C20: ='8'!F19+'8'!F13 -> 49239 | D20: ='1'!D20:E20 -> Payroll Expense | F20: =J40 -> 0 | H20: NIZARI (13 Checks) | J20: 23288.32 | K20: 2 | L20: 1100 | M20: 2:14PM | N20: 17 | P20: ='8'!Q20 -> 0 | R20: =Q20-P20 -> 0 | S20: 5 | T20: =R20*S20 -> 0
A21: ='1'!A21:B21 -> Cash From Bank | C21: 20000 | D21: ='1'!D21:E21 -> Other Cash Out | F21: =M53 -> 0 | K21: 3 | L21: 2440 | M21: 5:55PM | N21: 18 | P21: ='8'!Q21 -> 0 | R21: =Q21-P21 -> 0 | S21: 5 | T21: =R21*S21 -> 0
A22: ='1'!A22:B22 -> Other Cash In | C22: =J53 -> 122 | D22: TOTAL PAYOUTS | F22: =SUM(F5:F21)-F7-F8 -> 78281.32 | K22: 4 | L22: 1787 | M22: 8:55PM | N22: 19 | P22: ='8'!Q22 -> 0 | R22: =Q22-P22 -> 0 | S22: 5 | T22: =R22*S22 -> 0
A23: ='1'!A23:B23 -> Rebates & Commissions | C23: =F53 -> 0 | D23: Inside Over - (Short) | F23: =(F11+F14+F15+F16+F17+F18+F19+F20+F21+F5+F6)-(C17+C19+C20+C21+C22+C23) -> 356.88 | K23: 5 | N23: 20 | P23: ='8'!Q23 -> 0 | R23: =Q23-P23 -> 0 | S23: 5 | T23: =R23*S23 -> 0
A24: TOTAL RECEIPTS | C24: =SUM(C5:C23) -> 78280.6 | D24: Over All Over - (Short) | F24: =SUM(F22-C24) -> 0.72 | K24: 6 | N24: 21 | P24: ='8'!Q24 -> 0 | R24: =Q24-P24 -> 0 | S24: 5 | T24: =R24*S24 -> 0
A25: Out Side Over - (Short) | C25: =(F9+F10+F12+F13)-(C5+C6+C7+C8+C9+C10+C11+C12+C13+C14+C15+C16+C18) -> -356.16 | H25: TOTAL | J25: =SUM(J20:J24) -> 23288.32 | K25: 7 | N25: 22 | P25: ='8'!Q25 -> 0 | R25: =Q25-P25 -> 0 | S25: 5 | T25: =R25*S25 -> 0
A26: Cash Purchases | D26: Return Check Paid | K26: 8 | N26: 23 | P26: ='8'!Q26 -> 0 | R26: =Q26-P26 -> 0 | S26: 3 | T26: =R26*S26 -> 0
A27: Description | C27: Amount | D27: Description | F27: Amount | K27: 9 | N27: 24 | P27: ='8'!Q27 -> 0 | R27: =Q27-P27 -> 0 | S27: 3 | T27: =R27*S27 -> 0
